[Thu Sep 17 01:57:27.642327 2020] [wsgi:error] [pid 7240:tid 140021237708544] [remote 180.69.96.107:40249] mod_wsgi (pid=7240): Target WSGI script '/var/www/Appserver/flaskr/dodam.wsgi' cannot be loaded as Python module.
[Thu Sep 17 01:57:27.642387 2020] [wsgi:error] [pid 7240:tid 140021237708544] [remote 180.69.96.107:40249] mod_wsgi (pid=7240): Exception occurred processing WSGI script '/var/www/Appserver/flaskr/dodam.wsgi'.
[Thu Sep 17 01:57:27.642477 2020] [wsgi:error] [pid 7240:tid 140021237708544] [remote 180.69.96.107:40249] Traceback (most recent call last):
[Thu Sep 17 01:57:27.642512 2020] [wsgi:error] [pid 7240:tid 140021237708544] [remote 180.69.96.107:40249]   File "/var/www/Appserver/flaskr/dodam.wsgi", line 4, in <module>
[Thu Sep 17 01:57:27.642515 2020] [wsgi:error] [pid 7240:tid 140021237708544] [remote 180.69.96.107:40249]     from manage import app as application
[Thu Sep 17 01:57:27.642520 2020] [wsgi:error] [pid 7240:tid 140021237708544] [remote 180.69.96.107:40249]   File "/var/www/Appserver/flaskr/manage.py", line 15, in <module>
[Thu Sep 17 01:57:27.642523 2020] [wsgi:error] [pid 7240:tid 140021237708544] [remote 180.69.96.107:40249]     from config import config_by_name
[Thu Sep 17 01:57:27.642535 2020] [wsgi:error] [pid 7240:tid 140021237708544] [remote 180.69.96.107:40249]   File "/var/www/Appserver/flaskr/config.py", line 15
[Thu Sep 17 01:57:27.642543 2020] [wsgi:error] [pid 7240:tid 140021237708544] [remote 180.69.96.107:40249]     DB_URL = f"mysql+mysqlconnector://" + db['user'] + ":" + db['password'] + "@" + db['host'] + ":" + db['port'] + '/' + db['database'] + "?charset=utf8"
[Thu Sep 17 01:57:27.642581 2020] [wsgi:error] [pid 7240:tid 140021237708544] [remote 180.69.96.107:40249]                                       ^
[Thu Sep 17 01:57:27.642589 2020] [wsgi:error] [pid 7240:tid 140021237708544] [remote 180.69.96.107:40249] SyntaxError: invalid syntax
[Thu Sep 17 01:57:27.833132 2020] [wsgi:error] [pid 7240:tid 140021220923136] [remote 180.69.96.107:35129] mod_wsgi (pid=7240): Target WSGI script '/var/www/Appserver/flaskr/dodam.wsgi' cannot be loaded as Python module.
[Thu Sep 17 01:57:27.833169 2020] [wsgi:error] [pid 7240:tid 140021220923136] [remote 180.69.96.107:35129] mod_wsgi (pid=7240): Exception occurred processing WSGI script '/var/www/Appserver/flaskr/dodam.wsgi'.
[Thu Sep 17 01:57:27.833254 2020] [wsgi:error] [pid 7240:tid 140021220923136] [remote 180.69.96.107:35129] Traceback (most recent call last):
[Thu Sep 17 01:57:27.833287 2020] [wsgi:error] [pid 7240:tid 140021220923136] [remote 180.69.96.107:35129]   File "/var/www/Appserver/flaskr/dodam.wsgi", line 4, in <module>
[Thu Sep 17 01:57:27.833290 2020] [wsgi:error] [pid 7240:tid 140021220923136] [remote 180.69.96.107:35129]     from manage import app as application
[Thu Sep 17 01:57:27.833296 2020] [wsgi:error] [pid 7240:tid 140021220923136] [remote 180.69.96.107:35129]   File "/var/www/Appserver/flaskr/manage.py", line 15, in <module>
[Thu Sep 17 01:57:27.833298 2020] [wsgi:error] [pid 7240:tid 140021220923136] [remote 180.69.96.107:35129]     from config import config_by_name
[Thu Sep 17 01:57:27.833311 2020] [wsgi:error] [pid 7240:tid 140021220923136] [remote 180.69.96.107:35129]   File "/var/www/Appserver/flaskr/config.py", line 15
[Thu Sep 17 01:57:27.833318 2020] [wsgi:error] [pid 7240:tid 140021220923136] [remote 180.69.96.107:35129]     DB_URL = f"mysql+mysqlconnector://" + db['user'] + ":" + db['password'] + "@" + db['host'] + ":" + db['port'] + '/' + db['database'] + "?charset=utf8"
[Thu Sep 17 01:57:27.833343 2020] [wsgi:error] [pid 7240:tid 140021220923136] [remote 180.69.96.107:35129]                                       ^
[Thu Sep 17 01:57:27.833350 2020] [wsgi:error] [pid 7240:tid 140021220923136] [remote 180.69.96.107:35129] SyntaxError: invalid syntax
[Thu Sep 17 01:57:27.837555 2020] [wsgi:error] [pid 7240:tid 140021237708544] [remote 180.69.96.107:35129] mod_wsgi (pid=7240): Target WSGI script '/var/www/Appserver/flaskr/dodam.wsgi' cannot be loaded as Python module.
[Thu Sep 17 01:57:27.837581 2020] [wsgi:error] [pid 7240:tid 140021237708544] [remote 180.69.96.107:35129] mod_wsgi (pid=7240): Exception occurred processing WSGI script '/var/www/Appserver/flaskr/dodam.wsgi'.
[Thu Sep 17 01:57:27.837665 2020] [wsgi:error] [pid 7240:tid 140021237708544] [remote 180.69.96.107:35129] Traceback (most recent call last):
[Thu Sep 17 01:57:27.837685 2020] [wsgi:error] [pid 7240:tid 140021237708544] [remote 180.69.96.107:35129]   File "/var/www/Appserver/flaskr/dodam.wsgi", line 4, in <module>
[Thu Sep 17 01:57:27.837689 2020] [wsgi:error] [pid 7240:tid 140021237708544] [remote 180.69.96.107:35129]     from manage import app as application
[Thu Sep 17 01:57:27.837694 2020] [wsgi:error] [pid 7240:tid 140021237708544] [remote 180.69.96.107:35129]   File "/var/www/Appserver/flaskr/manage.py", line 15, in <module>
[Thu Sep 17 01:57:27.837697 2020] [wsgi:error] [pid 7240:tid 140021237708544] [remote 180.69.96.107:35129]     from config import config_by_name
[Thu Sep 17 01:57:27.837707 2020] [wsgi:error] [pid 7240:tid 140021237708544] [remote 180.69.96.107:35129]   File "/var/www/Appserver/flaskr/config.py", line 15
[Thu Sep 17 01:57:27.837715 2020] [wsgi:error] [pid 7240:tid 140021237708544] [remote 180.69.96.107:35129]     DB_URL = f"mysql+mysqlconnector://" + db['user'] + ":" + db['password'] + "@" + db['host'] + ":" + db['port'] + '/' + db['database'] + "?charset=utf8"
[Thu Sep 17 01:57:27.837734 2020] [wsgi:error] [pid 7240:tid 140021237708544] [remote 180.69.96.107:35129]                                       ^
[Thu Sep 17 01:57:27.837741 2020] [wsgi:error] [pid 7240:tid 140021237708544] [remote 180.69.96.107:35129] SyntaxError: invalid syntax
[Thu Sep 17 01:57:28.041130 2020] [wsgi:error] [pid 7240:tid 140021220923136] [remote 180.69.96.107:41273] mod_wsgi (pid=7240): Target WSGI script '/var/www/Appserver/flaskr/dodam.wsgi' cannot be loaded as Python module.
[Thu Sep 17 01:57:28.041179 2020] [wsgi:error] [pid 7240:tid 140021220923136] [remote 180.69.96.107:41273] mod_wsgi (pid=7240): Exception occurred processing WSGI script '/var/www/Appserver/flaskr/dodam.wsgi'.
[Thu Sep 17 01:57:28.041267 2020] [wsgi:error] [pid 7240:tid 140021220923136] [remote 180.69.96.107:41273] Traceback (most recent call last):
[Thu Sep 17 01:57:28.041288 2020] [wsgi:error] [pid 7240:tid 140021220923136] [remote 180.69.96.107:41273]   File "/var/www/Appserver/flaskr/dodam.wsgi", line 4, in <module>
[Thu Sep 17 01:57:28.041291 2020] [wsgi:error] [pid 7240:tid 140021220923136] [remote 180.69.96.107:41273]     from manage import app as application
[Thu Sep 17 01:57:28.041297 2020] [wsgi:error] [pid 7240:tid 140021220923136] [remote 180.69.96.107:41273]   File "/var/www/Appserver/flaskr/manage.py", line 15, in <module>
[Thu Sep 17 01:57:28.041299 2020] [wsgi:error] [pid 7240:tid 140021220923136] [remote 180.69.96.107:41273]     from config import config_by_name
[Thu Sep 17 01:57:28.041311 2020] [wsgi:error] [pid 7240:tid 140021220923136] [remote 180.69.96.107:41273]   File "/var/www/Appserver/flaskr/config.py", line 15
[Thu Sep 17 01:57:28.041318 2020] [wsgi:error] [pid 7240:tid 140021220923136] [remote 180.69.96.107:41273]     DB_URL = f"mysql+mysqlconnector://" + db['user'] + ":" + db['password'] + "@" + db['host'] + ":" + db['port'] + '/' + db['database'] + "?charset=utf8"
[Thu Sep 17 01:57:28.041343 2020] [wsgi:error] [pid 7240:tid 140021220923136] [remote 180.69.96.107:41273]                                       ^
[Thu Sep 17 01:57:28.041350 2020] [wsgi:error] [pid 7240:tid 140021220923136] [remote 180.69.96.107:41273] SyntaxError: invalid syntax
[Thu Sep 17 01:57:57.180455 2020] [wsgi:error] [pid 7240:tid 140021237708544] [remote 180.69.96.107:41273] mod_wsgi (pid=7240): Target WSGI script '/var/www/Appserver/flaskr/dodam.wsgi' cannot be loaded as Python module.
[Thu Sep 17 01:57:57.180512 2020] [wsgi:error] [pid 7240:tid 140021237708544] [remote 180.69.96.107:41273] mod_wsgi (pid=7240): Exception occurred processing WSGI script '/var/www/Appserver/flaskr/dodam.wsgi'.
[Thu Sep 17 01:57:57.180743 2020] [wsgi:error] [pid 7240:tid 140021237708544] [remote 180.69.96.107:41273] Traceback (most recent call last):
[Thu Sep 17 01:57:57.180785 2020] [wsgi:error] [pid 7240:tid 140021237708544] [remote 180.69.96.107:41273]   File "/var/www/Appserver/flaskr/dodam.wsgi", line 3, in <module>
[Thu Sep 17 01:57:57.180789 2020] [wsgi:error] [pid 7240:tid 140021237708544] [remote 180.69.96.107:41273]     hi
[Thu Sep 17 01:57:57.180805 2020] [wsgi:error] [pid 7240:tid 140021237708544] [remote 180.69.96.107:41273] NameError: name 'hi' is not defined
[Thu Sep 17 01:57:57.427476 2020] [wsgi:error] [pid 7240:tid 140021220923136] [remote 180.69.96.107:41273] mod_wsgi (pid=7240): Target WSGI script '/var/www/Appserver/flaskr/dodam.wsgi' cannot be loaded as Python module.
[Thu Sep 17 01:57:57.427544 2020] [wsgi:error] [pid 7240:tid 140021220923136] [remote 180.69.96.107:41273] mod_wsgi (pid=7240): Exception occurred processing WSGI script '/var/www/Appserver/flaskr/dodam.wsgi'.
[Thu Sep 17 01:57:57.427644 2020] [wsgi:error] [pid 7240:tid 140021220923136] [remote 180.69.96.107:41273] Traceback (most recent call last):
[Thu Sep 17 01:57:57.427666 2020] [wsgi:error] [pid 7240:tid 140021220923136] [remote 180.69.96.107:41273]   File "/var/www/Appserver/flaskr/dodam.wsgi", line 3, in <module>
[Thu Sep 17 01:57:57.427669 2020] [wsgi:error] [pid 7240:tid 140021220923136] [remote 180.69.96.107:41273]     hi
[Thu Sep 17 01:57:57.427684 2020] [wsgi:error] [pid 7240:tid 140021220923136] [remote 180.69.96.107:41273] NameError: name 'hi' is not defined
[Thu Sep 17 01:57:57.578532 2020] [wsgi:error] [pid 7240:tid 140021237708544] [remote 180.69.96.107:41273] mod_wsgi (pid=7240): Target WSGI script '/var/www/Appserver/flaskr/dodam.wsgi' cannot be loaded as Python module.
[Thu Sep 17 01:57:57.578566 2020] [wsgi:error] [pid 7240:tid 140021237708544] [remote 180.69.96.107:41273] mod_wsgi (pid=7240): Exception occurred processing WSGI script '/var/www/Appserver/flaskr/dodam.wsgi'.
[Thu Sep 17 01:57:57.578663 2020] [wsgi:error] [pid 7240:tid 140021237708544] [remote 180.69.96.107:41273] Traceback (most recent call last):
[Thu Sep 17 01:57:57.578683 2020] [wsgi:error] [pid 7240:tid 140021237708544] [remote 180.69.96.107:41273]   File "/var/www/Appserver/flaskr/dodam.wsgi", line 3, in <module>
[Thu Sep 17 01:57:57.578687 2020] [wsgi:error] [pid 7240:tid 140021237708544] [remote 180.69.96.107:41273]     hi
[Thu Sep 17 01:57:57.578701 2020] [wsgi:error] [pid 7240:tid 140021237708544] [remote 180.69.96.107:41273] NameError: name 'hi' is not defined
[Thu Sep 17 01:58:01.890545 2020] [wsgi:error] [pid 7240:tid 140021237708544] [remote 180.69.96.107:35129] mod_wsgi (pid=7240): Exception occurred processing WSGI script '/var/www/Appserver/flaskr/dodam.wsgi'.
[Thu Sep 17 01:58:01.890791 2020] [wsgi:error] [pid 7240:tid 140021220923136] [remote 180.69.96.107:40249] mod_wsgi (pid=7240): Exception occurred processing WSGI script '/var/www/Appserver/flaskr/dodam.wsgi'.
[Thu Sep 17 01:58:01.943985 2020] [wsgi:error] [pid 7240:tid 140021237708544] [remote 180.69.96.107:35129] Traceback (most recent call last):
[Thu Sep 17 01:58:01.944035 2020] [wsgi:error] [pid 7240:tid 140021237708544] [remote 180.69.96.107:35129]   File "/usr/local/lib/python3.5/dist-packages/flask/app.py", line 2464, in __call__
[Thu Sep 17 01:58:01.944039 2020] [wsgi:error] [pid 7240:tid 140021237708544] [remote 180.69.96.107:35129]     return self.wsgi_app(environ, start_response)
[Thu Sep 17 01:58:01.944045 2020] [wsgi:error] [pid 7240:tid 140021237708544] [remote 180.69.96.107:35129]   File "/usr/local/lib/python3.5/dist-packages/flask/app.py", line 2450, in wsgi_app
[Thu Sep 17 01:58:01.944048 2020] [wsgi:error] [pid 7240:tid 140021237708544] [remote 180.69.96.107:35129]     response = self.handle_exception(e)
[Thu Sep 17 01:58:01.944053 2020] [wsgi:error] [pid 7240:tid 140021237708544] [remote 180.69.96.107:35129]   File "/usr/local/lib/python3.5/dist-packages/flask/app.py", line 1867, in handle_exception
[Thu Sep 17 01:58:01.944067 2020] [wsgi:error] [pid 7240:tid 140021237708544] [remote 180.69.96.107:35129]     reraise(exc_type, exc_value, tb)
[Thu Sep 17 01:58:01.944072 2020] [wsgi:error] [pid 7240:tid 140021237708544] [remote 180.69.96.107:35129]   File "/usr/local/lib/python3.5/dist-packages/flask/_compat.py", line 39, in reraise
[Thu Sep 17 01:58:01.944081 2020] [wsgi:error] [pid 7240:tid 140021237708544] [remote 180.69.96.107:35129]     raise value
[Thu Sep 17 01:58:01.944086 2020] [wsgi:error] [pid 7240:tid 140021237708544] [remote 180.69.96.107:35129]   File "/usr/local/lib/python3.5/dist-packages/flask/app.py", line 2447, in wsgi_app
[Thu Sep 17 01:58:01.944088 2020] [wsgi:error] [pid 7240:tid 140021237708544] [remote 180.69.96.107:35129]     response = self.full_dispatch_request()
[Thu Sep 17 01:58:01.944093 2020] [wsgi:error] [pid 7240:tid 140021237708544] [remote 180.69.96.107:35129]   File "/usr/local/lib/python3.5/dist-packages/flask/app.py", line 1952, in full_dispatch_request
[Thu Sep 17 01:58:01.944095 2020] [wsgi:error] [pid 7240:tid 140021237708544] [remote 180.69.96.107:35129]     rv = self.handle_user_exception(e)
[Thu Sep 17 01:58:01.944099 2020] [wsgi:error] [pid 7240:tid 140021237708544] [remote 180.69.96.107:35129]   File "/usr/local/lib/python3.5/dist-packages/flask/app.py", line 1821, in handle_user_exception
[Thu Sep 17 01:58:01.944101 2020] [wsgi:error] [pid 7240:tid 140021237708544] [remote 180.69.96.107:35129]     reraise(exc_type, exc_value, tb)
[Thu Sep 17 01:58:01.944105 2020] [wsgi:error] [pid 7240:tid 140021237708544] [remote 180.69.96.107:35129]   File "/usr/local/lib/python3.5/dist-packages/flask/_compat.py", line 39, in reraise
[Thu Sep 17 01:58:01.944107 2020] [wsgi:error] [pid 7240:tid 140021237708544] [remote 180.69.96.107:35129]     raise value
[Thu Sep 17 01:58:01.944111 2020] [wsgi:error] [pid 7240:tid 140021237708544] [remote 180.69.96.107:35129]   File "/usr/local/lib/python3.5/dist-packages/flask/app.py", line 1950, in full_dispatch_request
[Thu Sep 17 01:58:01.944114 2020] [wsgi:error] [pid 7240:tid 140021237708544] [remote 180.69.96.107:35129]     rv = self.dispatch_request()
[Thu Sep 17 01:58:01.944118 2020] [wsgi:error] [pid 7240:tid 140021237708544] [remote 180.69.96.107:35129]   File "/usr/local/lib/python3.5/dist-packages/flask/app.py", line 1936, in dispatch_request
[Thu Sep 17 01:58:01.944120 2020] [wsgi:error] [pid 7240:tid 140021237708544] [remote 180.69.96.107:35129]     return self.view_functions[rule.endpoint](**req.view_args)
[Thu Sep 17 01:58:01.944124 2020] [wsgi:error] [pid 7240:tid 140021237708544] [remote 180.69.96.107:35129]   File "/var/www/Appserver/flaskr/manage.py", line 175, in show_entries
[Thu Sep 17 01:58:01.944126 2020] [wsgi:error] [pid 7240:tid 140021237708544] [remote 180.69.96.107:35129]     cur = g.db.execute('select title, text from entries order by id desc')
[Thu Sep 17 01:58:01.944131 2020] [wsgi:error] [pid 7240:tid 140021237708544] [remote 180.69.96.107:35129]   File "/usr/local/lib/python3.5/dist-packages/werkzeug/local.py", line 347, in __getattr__
[Thu Sep 17 01:58:01.944133 2020] [wsgi:error] [pid 7240:tid 140021237708544] [remote 180.69.96.107:35129]     return getattr(self._get_current_object(), name)
[Thu Sep 17 01:58:01.944148 2020] [wsgi:error] [pid 7240:tid 140021237708544] [remote 180.69.96.107:35129] AttributeError: '_AppCtxGlobals' object has no attribute 'db'
[Thu Sep 17 01:58:01.944533 2020] [wsgi:error] [pid 7240:tid 140021220923136] [remote 180.69.96.107:40249] Traceback (most recent call last):
[Thu Sep 17 01:58:01.944576 2020] [wsgi:error] [pid 7240:tid 140021220923136] [remote 180.69.96.107:40249]   File "/usr/local/lib/python3.5/dist-packages/flask/app.py", line 2464, in __call__
[Thu Sep 17 01:58:01.944580 2020] [wsgi:error] [pid 7240:tid 140021220923136] [remote 180.69.96.107:40249]     return self.wsgi_app(environ, start_response)
[Thu Sep 17 01:58:01.944585 2020] [wsgi:error] [pid 7240:tid 140021220923136] [remote 180.69.96.107:40249]   File "/usr/local/lib/python3.5/dist-packages/flask/app.py", line 2450, in wsgi_app
[Thu Sep 17 01:58:01.944587 2020] [wsgi:error] [pid 7240:tid 140021220923136] [remote 180.69.96.107:40249]     response = self.handle_exception(e)
[Thu Sep 17 01:58:01.944598 2020] [wsgi:error] [pid 7240:tid 140021220923136] [remote 180.69.96.107:40249]   File "/usr/local/lib/python3.5/dist-packages/flask/app.py", line 1867, in handle_exception
[Thu Sep 17 01:58:01.944600 2020] [wsgi:error] [pid 7240:tid 140021220923136] [remote 180.69.96.107:40249]     reraise(exc_type, exc_value, tb)
[Thu Sep 17 01:58:01.944605 2020] [wsgi:error] [pid 7240:tid 140021220923136] [remote 180.69.96.107:40249]   File "/usr/local/lib/python3.5/dist-packages/flask/_compat.py", line 39, in reraise
[Thu Sep 17 01:58:01.944607 2020] [wsgi:error] [pid 7240:tid 140021220923136] [remote 180.69.96.107:40249]     raise value
[Thu Sep 17 01:58:01.944611 2020] [wsgi:error] [pid 7240:tid 140021220923136] [remote 180.69.96.107:40249]   File "/usr/local/lib/python3.5/dist-packages/flask/app.py", line 2447, in wsgi_app
[Thu Sep 17 01:58:01.944614 2020] [wsgi:error] [pid 7240:tid 140021220923136] [remote 180.69.96.107:40249]     response = self.full_dispatch_request()
[Thu Sep 17 01:58:01.944618 2020] [wsgi:error] [pid 7240:tid 140021220923136] [remote 180.69.96.107:40249]   File "/usr/local/lib/python3.5/dist-packages/flask/app.py", line 1952, in full_dispatch_request
[Thu Sep 17 01:58:01.944620 2020] [wsgi:error] [pid 7240:tid 140021220923136] [remote 180.69.96.107:40249]     rv = self.handle_user_exception(e)
[Thu Sep 17 01:58:01.944625 2020] [wsgi:error] [pid 7240:tid 140021220923136] [remote 180.69.96.107:40249]   File "/usr/local/lib/python3.5/dist-packages/flask/app.py", line 1821, in handle_user_exception
[Thu Sep 17 01:58:01.944627 2020] [wsgi:error] [pid 7240:tid 140021220923136] [remote 180.69.96.107:40249]     reraise(exc_type, exc_value, tb)
[Thu Sep 17 01:58:01.944631 2020] [wsgi:error] [pid 7240:tid 140021220923136] [remote 180.69.96.107:40249]   File "/usr/local/lib/python3.5/dist-packages/flask/_compat.py", line 39, in reraise
[Thu Sep 17 01:58:01.944634 2020] [wsgi:error] [pid 7240:tid 140021220923136] [remote 180.69.96.107:40249]     raise value
[Thu Sep 17 01:58:01.944638 2020] [wsgi:error] [pid 7240:tid 140021220923136] [remote 180.69.96.107:40249]   File "/usr/local/lib/python3.5/dist-packages/flask/app.py", line 1950, in full_dispatch_request
[Thu Sep 17 01:58:01.944640 2020] [wsgi:error] [pid 7240:tid 140021220923136] [remote 180.69.96.107:40249]     rv = self.dispatch_request()
[Thu Sep 17 01:58:01.944644 2020] [wsgi:error] [pid 7240:tid 140021220923136] [remote 180.69.96.107:40249]   File "/usr/local/lib/python3.5/dist-packages/flask/app.py", line 1936, in dispatch_request
[Thu Sep 17 01:58:01.944647 2020] [wsgi:error] [pid 7240:tid 140021220923136] [remote 180.69.96.107:40249]     return self.view_functions[rule.endpoint](**req.view_args)
[Thu Sep 17 01:58:01.944651 2020] [wsgi:error] [pid 7240:tid 140021220923136] [remote 180.69.96.107:40249]   File "/var/www/Appserver/flaskr/manage.py", line 175, in show_entries
[Thu Sep 17 01:58:01.944654 2020] [wsgi:error] [pid 7240:tid 140021220923136] [remote 180.69.96.107:40249]     cur = g.db.execute('select title, text from entries order by id desc')
[Thu Sep 17 01:58:01.944658 2020] [wsgi:error] [pid 7240:tid 140021220923136] [remote 180.69.96.107:40249]   File "/usr/local/lib/python3.5/dist-packages/werkzeug/local.py", line 347, in __getattr__
[Thu Sep 17 01:58:01.944660 2020] [wsgi:error] [pid 7240:tid 140021220923136] [remote 180.69.96.107:40249]     return getattr(self._get_current_object(), name)
[Thu Sep 17 01:58:01.944673 2020] [wsgi:error] [pid 7240:tid 140021220923136] [remote 180.69.96.107:40249] AttributeError: '_AppCtxGlobals' object has no attribute 'db'
[Thu Sep 17 01:58:51.682689 2020] [wsgi:error] [pid 7240:tid 140021220923136] None
[Thu Sep 17 01:58:53.234784 2020] [wsgi:error] [pid 7240:tid 140021229315840] None
[Thu Sep 17 01:59:00.837414 2020] [wsgi:error] [pid 7240:tid 140021220923136] [remote 180.69.96.107:41273] mod_wsgi (pid=7240): Exception occurred processing WSGI script '/var/www/Appserver/flaskr/dodam.wsgi'.
[Thu Sep 17 01:59:00.851165 2020] [wsgi:error] [pid 7240:tid 140021220923136] [remote 180.69.96.107:41273] Traceback (most recent call last):
[Thu Sep 17 01:59:00.851241 2020] [wsgi:error] [pid 7240:tid 140021220923136] [remote 180.69.96.107:41273]   File "/usr/local/lib/python3.5/dist-packages/flask/app.py", line 2464, in __call__
[Thu Sep 17 01:59:00.851246 2020] [wsgi:error] [pid 7240:tid 140021220923136] [remote 180.69.96.107:41273]     return self.wsgi_app(environ, start_response)
[Thu Sep 17 01:59:00.851252 2020] [wsgi:error] [pid 7240:tid 140021220923136] [remote 180.69.96.107:41273]   File "/usr/local/lib/python3.5/dist-packages/flask/app.py", line 2450, in wsgi_app
[Thu Sep 17 01:59:00.851255 2020] [wsgi:error] [pid 7240:tid 140021220923136] [remote 180.69.96.107:41273]     response = self.handle_exception(e)
[Thu Sep 17 01:59:00.851260 2020] [wsgi:error] [pid 7240:tid 140021220923136] [remote 180.69.96.107:41273]   File "/usr/local/lib/python3.5/dist-packages/flask/app.py", line 1867, in handle_exception
[Thu Sep 17 01:59:00.851263 2020] [wsgi:error] [pid 7240:tid 140021220923136] [remote 180.69.96.107:41273]     reraise(exc_type, exc_value, tb)
[Thu Sep 17 01:59:00.851267 2020] [wsgi:error] [pid 7240:tid 140021220923136] [remote 180.69.96.107:41273]   File "/usr/local/lib/python3.5/dist-packages/flask/_compat.py", line 39, in reraise
[Thu Sep 17 01:59:00.851270 2020] [wsgi:error] [pid 7240:tid 140021220923136] [remote 180.69.96.107:41273]     raise value
[Thu Sep 17 01:59:00.851274 2020] [wsgi:error] [pid 7240:tid 140021220923136] [remote 180.69.96.107:41273]   File "/usr/local/lib/python3.5/dist-packages/flask/app.py", line 2447, in wsgi_app
[Thu Sep 17 01:59:00.851276 2020] [wsgi:error] [pid 7240:tid 140021220923136] [remote 180.69.96.107:41273]     response = self.full_dispatch_request()
[Thu Sep 17 01:59:00.851283 2020] [wsgi:error] [pid 7240:tid 140021220923136] [remote 180.69.96.107:41273]   File "/usr/local/lib/python3.5/dist-packages/flask/app.py", line 1952, in full_dispatch_request
[Thu Sep 17 01:59:00.851286 2020] [wsgi:error] [pid 7240:tid 140021220923136] [remote 180.69.96.107:41273]     rv = self.handle_user_exception(e)
[Thu Sep 17 01:59:00.851297 2020] [wsgi:error] [pid 7240:tid 140021220923136] [remote 180.69.96.107:41273]   File "/usr/local/lib/python3.5/dist-packages/flask/app.py", line 1821, in handle_user_exception
[Thu Sep 17 01:59:00.851300 2020] [wsgi:error] [pid 7240:tid 140021220923136] [remote 180.69.96.107:41273]     reraise(exc_type, exc_value, tb)
[Thu Sep 17 01:59:00.851304 2020] [wsgi:error] [pid 7240:tid 140021220923136] [remote 180.69.96.107:41273]   File "/usr/local/lib/python3.5/dist-packages/flask/_compat.py", line 39, in reraise
[Thu Sep 17 01:59:00.851307 2020] [wsgi:error] [pid 7240:tid 140021220923136] [remote 180.69.96.107:41273]     raise value
[Thu Sep 17 01:59:00.851311 2020] [wsgi:error] [pid 7240:tid 140021220923136] [remote 180.69.96.107:41273]   File "/usr/local/lib/python3.5/dist-packages/flask/app.py", line 1950, in full_dispatch_request
[Thu Sep 17 01:59:00.851313 2020] [wsgi:error] [pid 7240:tid 140021220923136] [remote 180.69.96.107:41273]     rv = self.dispatch_request()
[Thu Sep 17 01:59:00.851318 2020] [wsgi:error] [pid 7240:tid 140021220923136] [remote 180.69.96.107:41273]   File "/usr/local/lib/python3.5/dist-packages/flask/app.py", line 1936, in dispatch_request
[Thu Sep 17 01:59:00.851321 2020] [wsgi:error] [pid 7240:tid 140021220923136] [remote 180.69.96.107:41273]     return self.view_functions[rule.endpoint](**req.view_args)
[Thu Sep 17 01:59:00.851325 2020] [wsgi:error] [pid 7240:tid 140021220923136] [remote 180.69.96.107:41273]   File "/var/www/Appserver/flaskr/manage.py", line 152, in article
[Thu Sep 17 01:59:00.851328 2020] [wsgi:error] [pid 7240:tid 140021220923136] [remote 180.69.96.107:41273]     return json.dumps(latest_article)
[Thu Sep 17 01:59:00.851332 2020] [wsgi:error] [pid 7240:tid 140021220923136] [remote 180.69.96.107:41273]   File "/usr/lib/python3.5/json/__init__.py", line 230, in dumps
[Thu Sep 17 01:59:00.851334 2020] [wsgi:error] [pid 7240:tid 140021220923136] [remote 180.69.96.107:41273]     return _default_encoder.encode(obj)
[Thu Sep 17 01:59:00.851342 2020] [wsgi:error] [pid 7240:tid 140021220923136] [remote 180.69.96.107:41273]   File "/usr/lib/python3.5/json/encoder.py", line 198, in encode
[Thu Sep 17 01:59:00.851345 2020] [wsgi:error] [pid 7240:tid 140021220923136] [remote 180.69.96.107:41273]     chunks = self.iterencode(o, _one_shot=True)
[Thu Sep 17 01:59:00.851350 2020] [wsgi:error] [pid 7240:tid 140021220923136] [remote 180.69.96.107:41273]   File "/usr/lib/python3.5/json/encoder.py", line 256, in iterencode
[Thu Sep 17 01:59:00.851352 2020] [wsgi:error] [pid 7240:tid 140021220923136] [remote 180.69.96.107:41273]     return _iterencode(o, 0)
[Thu Sep 17 01:59:00.851356 2020] [wsgi:error] [pid 7240:tid 140021220923136] [remote 180.69.96.107:41273]   File "/usr/lib/python3.5/json/encoder.py", line 179, in default
[Thu Sep 17 01:59:00.851359 2020] [wsgi:error] [pid 7240:tid 140021220923136] [remote 180.69.96.107:41273]     raise TypeError(repr(o) + " is not JSON serializable")
[Thu Sep 17 01:59:00.851377 2020] [wsgi:error] [pid 7240:tid 140021220923136] [remote 180.69.96.107:41273] TypeError: (5, 8, '\xeb\x82\x9c \xec\xb0\xa8\xeb\x9d\xbc\xeb\xa6\xac \xec\x8a\xac\xed\x94\x94 \xec\x95\x84\xeb\x8a\x94 \xec\x82\x90\xec\x95\xa0\xeb\xa1\x9c\xea\xb0\x80 \xec\xa2\x8b\xec\x95\x84', '\xeb\xa9\x94\xea\xb0\x80\xec\x8a\xa4\xed\x84\xb0\xeb\x94\x94 \xea\xb0\x95\xec\x84\xb1\xea\xb7\x9c \xec\x84\xa0\xec\x83\x9d\xeb\x8b\x98 \xec\xa7\x84\xec\xa7\x9c \xeb\x8c\x80\xeb\xb0\x95\xec\x9d\xb8\xea\xb1\xb0 \xea\xb0\x99\xec\x95\x84!!!!!', 0, 0) is not JSON serializable
[Thu Sep 17 02:01:50.216988 2020] [wsgi:error] [pid 7955:tid 140021204129536] [remote 180.69.96.107:0] mod_wsgi (pid=7955): Target WSGI script '/var/www/Appserver/flaskr/dodam.wsgi' cannot be loaded as Python module.
[Thu Sep 17 02:01:50.217039 2020] [wsgi:error] [pid 7955:tid 140021204129536] [remote 180.69.96.107:0] mod_wsgi (pid=7955): Exception occurred processing WSGI script '/var/www/Appserver/flaskr/dodam.wsgi'.
[Thu Sep 17 02:01:50.217193 2020] [wsgi:error] [pid 7955:tid 140021204129536] [remote 180.69.96.107:0] Traceback (most recent call last):
[Thu Sep 17 02:01:50.217226 2020] [wsgi:error] [pid 7955:tid 140021204129536] [remote 180.69.96.107:0]   File "/var/www/Appserver/flaskr/dodam.wsgi", line 3, in <module>
[Thu Sep 17 02:01:50.217231 2020] [wsgi:error] [pid 7955:tid 140021204129536] [remote 180.69.96.107:0]     hi
[Thu Sep 17 02:01:50.217244 2020] [wsgi:error] [pid 7955:tid 140021204129536] [remote 180.69.96.107:0] NameError: name 'hi' is not defined
[Thu Sep 17 02:02:01.604008 2020] [wsgi:error] [pid 7955:tid 140021212530432] [remote 180.69.96.107:39225] mod_wsgi (pid=7955): Target WSGI script '/var/www/Appserver/flaskr/dodam.wsgi' cannot be loaded as Python module.
[Thu Sep 17 02:02:01.604071 2020] [wsgi:error] [pid 7955:tid 140021212530432] [remote 180.69.96.107:39225] mod_wsgi (pid=7955): Exception occurred processing WSGI script '/var/www/Appserver/flaskr/dodam.wsgi'.
[Thu Sep 17 02:02:01.604169 2020] [wsgi:error] [pid 7955:tid 140021212530432] [remote 180.69.96.107:39225] Traceback (most recent call last):
[Thu Sep 17 02:02:01.604192 2020] [wsgi:error] [pid 7955:tid 140021212530432] [remote 180.69.96.107:39225]   File "/var/www/Appserver/flaskr/dodam.wsgi", line 3, in <module>
[Thu Sep 17 02:02:01.604195 2020] [wsgi:error] [pid 7955:tid 140021212530432] [remote 180.69.96.107:39225]     hi
[Thu Sep 17 02:02:01.604212 2020] [wsgi:error] [pid 7955:tid 140021212530432] [remote 180.69.96.107:39225] NameError: name 'hi' is not defined
[Thu Sep 17 02:02:09.934606 2020] [wsgi:error] [pid 7955:tid 140021204129536] [remote 180.69.96.107:39225] mod_wsgi (pid=7955): Exception occurred processing WSGI script '/var/www/Appserver/flaskr/dodam.wsgi'.
[Thu Sep 17 02:02:09.936005 2020] [wsgi:error] [pid 7955:tid 140021204129536] [remote 180.69.96.107:39225] Traceback (most recent call last):
[Thu Sep 17 02:02:09.936061 2020] [wsgi:error] [pid 7955:tid 140021204129536] [remote 180.69.96.107:39225]   File "/usr/local/lib/python3.5/dist-packages/flask/app.py", line 2464, in __call__
[Thu Sep 17 02:02:09.936074 2020] [wsgi:error] [pid 7955:tid 140021204129536] [remote 180.69.96.107:39225]     return self.wsgi_app(environ, start_response)
[Thu Sep 17 02:02:09.936081 2020] [wsgi:error] [pid 7955:tid 140021204129536] [remote 180.69.96.107:39225]   File "/usr/local/lib/python3.5/dist-packages/flask/app.py", line 2450, in wsgi_app
[Thu Sep 17 02:02:09.936084 2020] [wsgi:error] [pid 7955:tid 140021204129536] [remote 180.69.96.107:39225]     response = self.handle_exception(e)
[Thu Sep 17 02:02:09.936089 2020] [wsgi:error] [pid 7955:tid 140021204129536] [remote 180.69.96.107:39225]   File "/usr/local/lib/python3.5/dist-packages/flask/app.py", line 1867, in handle_exception
[Thu Sep 17 02:02:09.936091 2020] [wsgi:error] [pid 7955:tid 140021204129536] [remote 180.69.96.107:39225]     reraise(exc_type, exc_value, tb)
[Thu Sep 17 02:02:09.936096 2020] [wsgi:error] [pid 7955:tid 140021204129536] [remote 180.69.96.107:39225]   File "/usr/local/lib/python3.5/dist-packages/flask/_compat.py", line 39, in reraise
[Thu Sep 17 02:02:09.936098 2020] [wsgi:error] [pid 7955:tid 140021204129536] [remote 180.69.96.107:39225]     raise value
[Thu Sep 17 02:02:09.936103 2020] [wsgi:error] [pid 7955:tid 140021204129536] [remote 180.69.96.107:39225]   File "/usr/local/lib/python3.5/dist-packages/flask/app.py", line 2447, in wsgi_app
[Thu Sep 17 02:02:09.936105 2020] [wsgi:error] [pid 7955:tid 140021204129536] [remote 180.69.96.107:39225]     response = self.full_dispatch_request()
[Thu Sep 17 02:02:09.936110 2020] [wsgi:error] [pid 7955:tid 140021204129536] [remote 180.69.96.107:39225]   File "/usr/local/lib/python3.5/dist-packages/flask/app.py", line 1952, in full_dispatch_request
[Thu Sep 17 02:02:09.936112 2020] [wsgi:error] [pid 7955:tid 140021204129536] [remote 180.69.96.107:39225]     rv = self.handle_user_exception(e)
[Thu Sep 17 02:02:09.936117 2020] [wsgi:error] [pid 7955:tid 140021204129536] [remote 180.69.96.107:39225]   File "/usr/local/lib/python3.5/dist-packages/flask/app.py", line 1821, in handle_user_exception
[Thu Sep 17 02:02:09.936119 2020] [wsgi:error] [pid 7955:tid 140021204129536] [remote 180.69.96.107:39225]     reraise(exc_type, exc_value, tb)
[Thu Sep 17 02:02:09.936123 2020] [wsgi:error] [pid 7955:tid 140021204129536] [remote 180.69.96.107:39225]   File "/usr/local/lib/python3.5/dist-packages/flask/_compat.py", line 39, in reraise
[Thu Sep 17 02:02:09.936126 2020] [wsgi:error] [pid 7955:tid 140021204129536] [remote 180.69.96.107:39225]     raise value
[Thu Sep 17 02:02:09.936130 2020] [wsgi:error] [pid 7955:tid 140021204129536] [remote 180.69.96.107:39225]   File "/usr/local/lib/python3.5/dist-packages/flask/app.py", line 1950, in full_dispatch_request
[Thu Sep 17 02:02:09.936133 2020] [wsgi:error] [pid 7955:tid 140021204129536] [remote 180.69.96.107:39225]     rv = self.dispatch_request()
[Thu Sep 17 02:02:09.936137 2020] [wsgi:error] [pid 7955:tid 140021204129536] [remote 180.69.96.107:39225]   File "/usr/local/lib/python3.5/dist-packages/flask/app.py", line 1936, in dispatch_request
[Thu Sep 17 02:02:09.936140 2020] [wsgi:error] [pid 7955:tid 140021204129536] [remote 180.69.96.107:39225]     return self.view_functions[rule.endpoint](**req.view_args)
[Thu Sep 17 02:02:09.936144 2020] [wsgi:error] [pid 7955:tid 140021204129536] [remote 180.69.96.107:39225]   File "/var/www/Appserver/flaskr/manage.py", line 152, in article
[Thu Sep 17 02:02:09.936146 2020] [wsgi:error] [pid 7955:tid 140021204129536] [remote 180.69.96.107:39225]     return json.dumps(latest_article, ensure_ascii=False, indent=4)
[Thu Sep 17 02:02:09.936151 2020] [wsgi:error] [pid 7955:tid 140021204129536] [remote 180.69.96.107:39225]   File "/usr/lib/python3.5/json/__init__.py", line 237, in dumps
[Thu Sep 17 02:02:09.936153 2020] [wsgi:error] [pid 7955:tid 140021204129536] [remote 180.69.96.107:39225]     **kw).encode(obj)
[Thu Sep 17 02:02:09.936157 2020] [wsgi:error] [pid 7955:tid 140021204129536] [remote 180.69.96.107:39225]   File "/usr/lib/python3.5/json/encoder.py", line 200, in encode
[Thu Sep 17 02:02:09.936160 2020] [wsgi:error] [pid 7955:tid 140021204129536] [remote 180.69.96.107:39225]     chunks = list(chunks)
[Thu Sep 17 02:02:09.936167 2020] [wsgi:error] [pid 7955:tid 140021204129536] [remote 180.69.96.107:39225]   File "/usr/lib/python3.5/json/encoder.py", line 436, in _iterencode
[Thu Sep 17 02:02:09.936170 2020] [wsgi:error] [pid 7955:tid 140021204129536] [remote 180.69.96.107:39225]     o = _default(o)
[Thu Sep 17 02:02:09.936174 2020] [wsgi:error] [pid 7955:tid 140021204129536] [remote 180.69.96.107:39225]   File "/usr/lib/python3.5/json/encoder.py", line 179, in default
[Thu Sep 17 02:02:09.936177 2020] [wsgi:error] [pid 7955:tid 140021204129536] [remote 180.69.96.107:39225]     raise TypeError(repr(o) + " is not JSON serializable")
[Thu Sep 17 02:02:09.936192 2020] [wsgi:error] [pid 7955:tid 140021204129536] [remote 180.69.96.107:39225] TypeError: (5, 8, '\xeb\x82\x9c \xec\xb0\xa8\xeb\x9d\xbc\xeb\xa6\xac \xec\x8a\xac\xed\x94\x94 \xec\x95\x84\xeb\x8a\x94 \xec\x82\x90\xec\x95\xa0\xeb\xa1\x9c\xea\xb0\x80 \xec\xa2\x8b\xec\x95\x84', '\xeb\xa9\x94\xea\xb0\x80\xec\x8a\xa4\xed\x84\xb0\xeb\x94\x94 \xea\xb0\x95\xec\x84\xb1\xea\xb7\x9c \xec\x84\xa0\xec\x83\x9d\xeb\x8b\x98 \xec\xa7\x84\xec\xa7\x9c \xeb\x8c\x80\xeb\xb0\x95\xec\x9d\xb8\xea\xb1\xb0 \xea\xb0\x99\xec\x95\x84!!!!!', 0, 0) is not JSON serializable
[Thu Sep 17 02:05:08.391993 2020] [wsgi:error] [pid 8117:tid 140021212530432] [remote 180.69.96.107:40249] mod_wsgi (pid=8117): Target WSGI script '/var/www/Appserver/flaskr/dodam.wsgi' cannot be loaded as Python module.
[Thu Sep 17 02:05:08.392050 2020] [wsgi:error] [pid 8117:tid 140021212530432] [remote 180.69.96.107:40249] mod_wsgi (pid=8117): Exception occurred processing WSGI script '/var/www/Appserver/flaskr/dodam.wsgi'.
[Thu Sep 17 02:05:08.392208 2020] [wsgi:error] [pid 8117:tid 140021212530432] [remote 180.69.96.107:40249] Traceback (most recent call last):
[Thu Sep 17 02:05:08.392230 2020] [wsgi:error] [pid 8117:tid 140021212530432] [remote 180.69.96.107:40249]   File "/var/www/Appserver/flaskr/dodam.wsgi", line 3, in <module>
[Thu Sep 17 02:05:08.392235 2020] [wsgi:error] [pid 8117:tid 140021212530432] [remote 180.69.96.107:40249]     hi
[Thu Sep 17 02:05:08.392249 2020] [wsgi:error] [pid 8117:tid 140021212530432] [remote 180.69.96.107:40249] NameError: name 'hi' is not defined
[Thu Sep 17 02:05:08.392594 2020] [wsgi:error] [pid 8117:tid 140021220923136] [remote 180.69.96.107:39993] mod_wsgi (pid=8117): Target WSGI script '/var/www/Appserver/flaskr/dodam.wsgi' cannot be loaded as Python module.
[Thu Sep 17 02:05:08.392620 2020] [wsgi:error] [pid 8117:tid 140021220923136] [remote 180.69.96.107:39993] mod_wsgi (pid=8117): Exception occurred processing WSGI script '/var/www/Appserver/flaskr/dodam.wsgi'.
[Thu Sep 17 02:05:08.392671 2020] [wsgi:error] [pid 8117:tid 140021220923136] [remote 180.69.96.107:39993] Traceback (most recent call last):
[Thu Sep 17 02:05:08.392692 2020] [wsgi:error] [pid 8117:tid 140021220923136] [remote 180.69.96.107:39993]   File "/var/www/Appserver/flaskr/dodam.wsgi", line 3, in <module>
[Thu Sep 17 02:05:08.392695 2020] [wsgi:error] [pid 8117:tid 140021220923136] [remote 180.69.96.107:39993]     hi
[Thu Sep 17 02:05:08.392708 2020] [wsgi:error] [pid 8117:tid 140021220923136] [remote 180.69.96.107:39993] NameError: name 'hi' is not defined
[Thu Sep 17 02:05:08.393005 2020] [wsgi:error] [pid 8117:tid 140021204129536] [remote 180.69.96.107:0] mod_wsgi (pid=8117): Target WSGI script '/var/www/Appserver/flaskr/dodam.wsgi' cannot be loaded as Python module.
[Thu Sep 17 02:05:08.393027 2020] [wsgi:error] [pid 8117:tid 140021204129536] [remote 180.69.96.107:0] mod_wsgi (pid=8117): Exception occurred processing WSGI script '/var/www/Appserver/flaskr/dodam.wsgi'.
[Thu Sep 17 02:05:08.393075 2020] [wsgi:error] [pid 8117:tid 140021204129536] [remote 180.69.96.107:0] Traceback (most recent call last):
[Thu Sep 17 02:05:08.393092 2020] [wsgi:error] [pid 8117:tid 140021204129536] [remote 180.69.96.107:0]   File "/var/www/Appserver/flaskr/dodam.wsgi", line 3, in <module>
[Thu Sep 17 02:05:08.393096 2020] [wsgi:error] [pid 8117:tid 140021204129536] [remote 180.69.96.107:0]     hi
[Thu Sep 17 02:05:08.393116 2020] [wsgi:error] [pid 8117:tid 140021204129536] [remote 180.69.96.107:0] NameError: name 'hi' is not defined
[Thu Sep 17 02:05:12.134845 2020] [wsgi:error] [pid 8117:tid 140021229315840] [remote 180.69.96.107:38969] mod_wsgi (pid=8117): Exception occurred processing WSGI script '/var/www/Appserver/flaskr/dodam.wsgi'.
[Thu Sep 17 02:05:12.135965 2020] [wsgi:error] [pid 8117:tid 140021204129536] [remote 180.69.96.107:41273] mod_wsgi (pid=8117): Exception occurred processing WSGI script '/var/www/Appserver/flaskr/dodam.wsgi'.
[Thu Sep 17 02:05:12.136401 2020] [wsgi:error] [pid 8117:tid 140021204129536] [remote 180.69.96.107:41273] Traceback (most recent call last):
[Thu Sep 17 02:05:12.136493 2020] [wsgi:error] [pid 8117:tid 140021204129536] [remote 180.69.96.107:41273]   File "/usr/local/lib/python3.5/dist-packages/flask/app.py", line 2464, in __call__
[Thu Sep 17 02:05:12.136498 2020] [wsgi:error] [pid 8117:tid 140021204129536] [remote 180.69.96.107:41273]     return self.wsgi_app(environ, start_response)
[Thu Sep 17 02:05:12.136503 2020] [wsgi:error] [pid 8117:tid 140021204129536] [remote 180.69.96.107:41273]   File "/usr/local/lib/python3.5/dist-packages/flask/app.py", line 2450, in wsgi_app
[Thu Sep 17 02:05:12.136506 2020] [wsgi:error] [pid 8117:tid 140021204129536] [remote 180.69.96.107:41273]     response = self.handle_exception(e)
[Thu Sep 17 02:05:12.136511 2020] [wsgi:error] [pid 8117:tid 140021204129536] [remote 180.69.96.107:41273]   File "/usr/local/lib/python3.5/dist-packages/flask/app.py", line 1867, in handle_exception
[Thu Sep 17 02:05:12.136513 2020] [wsgi:error] [pid 8117:tid 140021204129536] [remote 180.69.96.107:41273]     reraise(exc_type, exc_value, tb)
[Thu Sep 17 02:05:12.136518 2020] [wsgi:error] [pid 8117:tid 140021204129536] [remote 180.69.96.107:41273]   File "/usr/local/lib/python3.5/dist-packages/flask/_compat.py", line 39, in reraise
[Thu Sep 17 02:05:12.136521 2020] [wsgi:error] [pid 8117:tid 140021204129536] [remote 180.69.96.107:41273]     raise value
[Thu Sep 17 02:05:12.136525 2020] [wsgi:error] [pid 8117:tid 140021204129536] [remote 180.69.96.107:41273]   File "/usr/local/lib/python3.5/dist-packages/flask/app.py", line 2447, in wsgi_app
[Thu Sep 17 02:05:12.136528 2020] [wsgi:error] [pid 8117:tid 140021204129536] [remote 180.69.96.107:41273]     response = self.full_dispatch_request()
[Thu Sep 17 02:05:12.136532 2020] [wsgi:error] [pid 8117:tid 140021204129536] [remote 180.69.96.107:41273]   File "/usr/local/lib/python3.5/dist-packages/flask/app.py", line 1952, in full_dispatch_request
[Thu Sep 17 02:05:12.136535 2020] [wsgi:error] [pid 8117:tid 140021204129536] [remote 180.69.96.107:41273]     rv = self.handle_user_exception(e)
[Thu Sep 17 02:05:12.136539 2020] [wsgi:error] [pid 8117:tid 140021204129536] [remote 180.69.96.107:41273]   File "/usr/local/lib/python3.5/dist-packages/flask/app.py", line 1821, in handle_user_exception
[Thu Sep 17 02:05:12.136541 2020] [wsgi:error] [pid 8117:tid 140021204129536] [remote 180.69.96.107:41273]     reraise(exc_type, exc_value, tb)
[Thu Sep 17 02:05:12.136545 2020] [wsgi:error] [pid 8117:tid 140021204129536] [remote 180.69.96.107:41273]   File "/usr/local/lib/python3.5/dist-packages/flask/_compat.py", line 39, in reraise
[Thu Sep 17 02:05:12.136547 2020] [wsgi:error] [pid 8117:tid 140021204129536] [remote 180.69.96.107:41273]     raise value
[Thu Sep 17 02:05:12.136551 2020] [wsgi:error] [pid 8117:tid 140021204129536] [remote 180.69.96.107:41273]   File "/usr/local/lib/python3.5/dist-packages/flask/app.py", line 1950, in full_dispatch_request
[Thu Sep 17 02:05:12.136554 2020] [wsgi:error] [pid 8117:tid 140021204129536] [remote 180.69.96.107:41273]     rv = self.dispatch_request()
[Thu Sep 17 02:05:12.136558 2020] [wsgi:error] [pid 8117:tid 140021204129536] [remote 180.69.96.107:41273]   File "/usr/local/lib/python3.5/dist-packages/flask/app.py", line 1936, in dispatch_request
[Thu Sep 17 02:05:12.136560 2020] [wsgi:error] [pid 8117:tid 140021204129536] [remote 180.69.96.107:41273]     return self.view_functions[rule.endpoint](**req.view_args)
[Thu Sep 17 02:05:12.136572 2020] [wsgi:error] [pid 8117:tid 140021204129536] [remote 180.69.96.107:41273]   File "/var/www/Appserver/flaskr/manage.py", line 153, in article
[Thu Sep 17 02:05:12.136575 2020] [wsgi:error] [pid 8117:tid 140021204129536] [remote 180.69.96.107:41273]     return json.dumps(latest_article, ensure_ascii=False, indent=4)
[Thu Sep 17 02:05:12.136579 2020] [wsgi:error] [pid 8117:tid 140021204129536] [remote 180.69.96.107:41273]   File "/usr/lib/python3.5/json/__init__.py", line 237, in dumps
[Thu Sep 17 02:05:12.136581 2020] [wsgi:error] [pid 8117:tid 140021204129536] [remote 180.69.96.107:41273]     **kw).encode(obj)
[Thu Sep 17 02:05:12.136586 2020] [wsgi:error] [pid 8117:tid 140021204129536] [remote 180.69.96.107:41273]   File "/usr/lib/python3.5/json/encoder.py", line 200, in encode
[Thu Sep 17 02:05:12.136588 2020] [wsgi:error] [pid 8117:tid 140021204129536] [remote 180.69.96.107:41273]     chunks = list(chunks)
[Thu Sep 17 02:05:12.136592 2020] [wsgi:error] [pid 8117:tid 140021204129536] [remote 180.69.96.107:41273]   File "/usr/lib/python3.5/json/encoder.py", line 436, in _iterencode
[Thu Sep 17 02:05:12.136594 2020] [wsgi:error] [pid 8117:tid 140021204129536] [remote 180.69.96.107:41273]     o = _default(o)
[Thu Sep 17 02:05:12.136598 2020] [wsgi:error] [pid 8117:tid 140021204129536] [remote 180.69.96.107:41273]   File "/usr/lib/python3.5/json/encoder.py", line 179, in default
[Thu Sep 17 02:05:12.136601 2020] [wsgi:error] [pid 8117:tid 140021204129536] [remote 180.69.96.107:41273]     raise TypeError(repr(o) + " is not JSON serializable")
[Thu Sep 17 02:05:12.136615 2020] [wsgi:error] [pid 8117:tid 140021204129536] [remote 180.69.96.107:41273] TypeError: (5, 8, '\xeb\x82\x9c \xec\xb0\xa8\xeb\x9d\xbc\xeb\xa6\xac \xec\x8a\xac\xed\x94\x94 \xec\x95\x84\xeb\x8a\x94 \xec\x82\x90\xec\x95\xa0\xeb\xa1\x9c\xea\xb0\x80 \xec\xa2\x8b\xec\x95\x84', '\xeb\xa9\x94\xea\xb0\x80\xec\x8a\xa4\xed\x84\xb0\xeb\x94\x94 \xea\xb0\x95\xec\x84\xb1\xea\xb7\x9c \xec\x84\xa0\xec\x83\x9d\xeb\x8b\x98 \xec\xa7\x84\xec\xa7\x9c \xeb\x8c\x80\xeb\xb0\x95\xec\x9d\xb8\xea\xb1\xb0 \xea\xb0\x99\xec\x95\x84!!!!!', 0, 0) is not JSON serializable
[Thu Sep 17 02:05:12.136932 2020] [wsgi:error] [pid 8117:tid 140021229315840] [remote 180.69.96.107:38969] Traceback (most recent call last):
[Thu Sep 17 02:05:12.136978 2020] [wsgi:error] [pid 8117:tid 140021229315840] [remote 180.69.96.107:38969]   File "/usr/local/lib/python3.5/dist-packages/flask/app.py", line 2464, in __call__
[Thu Sep 17 02:05:12.136982 2020] [wsgi:error] [pid 8117:tid 140021229315840] [remote 180.69.96.107:38969]     return self.wsgi_app(environ, start_response)
[Thu Sep 17 02:05:12.136987 2020] [wsgi:error] [pid 8117:tid 140021229315840] [remote 180.69.96.107:38969]   File "/usr/local/lib/python3.5/dist-packages/flask/app.py", line 2450, in wsgi_app
[Thu Sep 17 02:05:12.136989 2020] [wsgi:error] [pid 8117:tid 140021229315840] [remote 180.69.96.107:38969]     response = self.handle_exception(e)
[Thu Sep 17 02:05:12.136993 2020] [wsgi:error] [pid 8117:tid 140021229315840] [remote 180.69.96.107:38969]   File "/usr/local/lib/python3.5/dist-packages/flask/app.py", line 1867, in handle_exception
[Thu Sep 17 02:05:12.136996 2020] [wsgi:error] [pid 8117:tid 140021229315840] [remote 180.69.96.107:38969]     reraise(exc_type, exc_value, tb)
[Thu Sep 17 02:05:12.137000 2020] [wsgi:error] [pid 8117:tid 140021229315840] [remote 180.69.96.107:38969]   File "/usr/local/lib/python3.5/dist-packages/flask/_compat.py", line 39, in reraise
[Thu Sep 17 02:05:12.137002 2020] [wsgi:error] [pid 8117:tid 140021229315840] [remote 180.69.96.107:38969]     raise value
[Thu Sep 17 02:05:12.137006 2020] [wsgi:error] [pid 8117:tid 140021229315840] [remote 180.69.96.107:38969]   File "/usr/local/lib/python3.5/dist-packages/flask/app.py", line 2447, in wsgi_app
[Thu Sep 17 02:05:12.137008 2020] [wsgi:error] [pid 8117:tid 140021229315840] [remote 180.69.96.107:38969]     response = self.full_dispatch_request()
[Thu Sep 17 02:05:12.137018 2020] [wsgi:error] [pid 8117:tid 140021229315840] [remote 180.69.96.107:38969]   File "/usr/local/lib/python3.5/dist-packages/flask/app.py", line 1952, in full_dispatch_request
[Thu Sep 17 02:05:12.137020 2020] [wsgi:error] [pid 8117:tid 140021229315840] [remote 180.69.96.107:38969]     rv = self.handle_user_exception(e)
[Thu Sep 17 02:05:12.137025 2020] [wsgi:error] [pid 8117:tid 140021229315840] [remote 180.69.96.107:38969]   File "/usr/local/lib/python3.5/dist-packages/flask/app.py", line 1821, in handle_user_exception
[Thu Sep 17 02:05:12.137027 2020] [wsgi:error] [pid 8117:tid 140021229315840] [remote 180.69.96.107:38969]     reraise(exc_type, exc_value, tb)
[Thu Sep 17 02:05:12.137031 2020] [wsgi:error] [pid 8117:tid 140021229315840] [remote 180.69.96.107:38969]   File "/usr/local/lib/python3.5/dist-packages/flask/_compat.py", line 39, in reraise
[Thu Sep 17 02:05:12.137033 2020] [wsgi:error] [pid 8117:tid 140021229315840] [remote 180.69.96.107:38969]     raise value
[Thu Sep 17 02:05:12.137037 2020] [wsgi:error] [pid 8117:tid 140021229315840] [remote 180.69.96.107:38969]   File "/usr/local/lib/python3.5/dist-packages/flask/app.py", line 1950, in full_dispatch_request
[Thu Sep 17 02:05:12.137040 2020] [wsgi:error] [pid 8117:tid 140021229315840] [remote 180.69.96.107:38969]     rv = self.dispatch_request()
[Thu Sep 17 02:05:12.137044 2020] [wsgi:error] [pid 8117:tid 140021229315840] [remote 180.69.96.107:38969]   File "/usr/local/lib/python3.5/dist-packages/flask/app.py", line 1936, in dispatch_request
[Thu Sep 17 02:05:12.137046 2020] [wsgi:error] [pid 8117:tid 140021229315840] [remote 180.69.96.107:38969]     return self.view_functions[rule.endpoint](**req.view_args)
[Thu Sep 17 02:05:12.137050 2020] [wsgi:error] [pid 8117:tid 140021229315840] [remote 180.69.96.107:38969]   File "/var/www/Appserver/flaskr/manage.py", line 153, in article
[Thu Sep 17 02:05:12.137052 2020] [wsgi:error] [pid 8117:tid 140021229315840] [remote 180.69.96.107:38969]     return json.dumps(latest_article, ensure_ascii=False, indent=4)
[Thu Sep 17 02:05:12.137056 2020] [wsgi:error] [pid 8117:tid 140021229315840] [remote 180.69.96.107:38969]   File "/usr/lib/python3.5/json/__init__.py", line 237, in dumps
[Thu Sep 17 02:05:12.137059 2020] [wsgi:error] [pid 8117:tid 140021229315840] [remote 180.69.96.107:38969]     **kw).encode(obj)
[Thu Sep 17 02:05:12.137063 2020] [wsgi:error] [pid 8117:tid 140021229315840] [remote 180.69.96.107:38969]   File "/usr/lib/python3.5/json/encoder.py", line 200, in encode
[Thu Sep 17 02:05:12.137065 2020] [wsgi:error] [pid 8117:tid 140021229315840] [remote 180.69.96.107:38969]     chunks = list(chunks)
[Thu Sep 17 02:05:12.137069 2020] [wsgi:error] [pid 8117:tid 140021229315840] [remote 180.69.96.107:38969]   File "/usr/lib/python3.5/json/encoder.py", line 436, in _iterencode
[Thu Sep 17 02:05:12.137071 2020] [wsgi:error] [pid 8117:tid 140021229315840] [remote 180.69.96.107:38969]     o = _default(o)
[Thu Sep 17 02:05:12.137075 2020] [wsgi:error] [pid 8117:tid 140021229315840] [remote 180.69.96.107:38969]   File "/usr/lib/python3.5/json/encoder.py", line 179, in default
[Thu Sep 17 02:05:12.137077 2020] [wsgi:error] [pid 8117:tid 140021229315840] [remote 180.69.96.107:38969]     raise TypeError(repr(o) + " is not JSON serializable")
[Thu Sep 17 02:05:12.137090 2020] [wsgi:error] [pid 8117:tid 140021229315840] [remote 180.69.96.107:38969] TypeError: (5, 8, '\xeb\x82\x9c \xec\xb0\xa8\xeb\x9d\xbc\xeb\xa6\xac \xec\x8a\xac\xed\x94\x94 \xec\x95\x84\xeb\x8a\x94 \xec\x82\x90\xec\x95\xa0\xeb\xa1\x9c\xea\xb0\x80 \xec\xa2\x8b\xec\x95\x84', '\xeb\xa9\x94\xea\xb0\x80\xec\x8a\xa4\xed\x84\xb0\xeb\x94\x94 \xea\xb0\x95\xec\x84\xb1\xea\xb7\x9c \xec\x84\xa0\xec\x83\x9d\xeb\x8b\x98 \xec\xa7\x84\xec\xa7\x9c \xeb\x8c\x80\xeb\xb0\x95\xec\x9d\xb8\xea\xb1\xb0 \xea\xb0\x99\xec\x95\x84!!!!!', 0, 0) is not JSON serializable
