[Thu Sep 17 02:46:49.222560 2020] [wsgi:error] [pid 10164:tid 139768390559488] [remote 180.69.96.107:0] mod_wsgi (pid=10164): Exception occurred processing WSGI script '/var/www/Appserver/flaskr/dodam.wsgi'.
[Thu Sep 17 02:46:49.226584 2020] [wsgi:error] [pid 10164:tid 139768390559488] [remote 180.69.96.107:0] Traceback (most recent call last):
[Thu Sep 17 02:46:49.226630 2020] [wsgi:error] [pid 10164:tid 139768390559488] [remote 180.69.96.107:0]   File "/usr/local/lib/python3.5/dist-packages/sqlalchemy/engine/base.py", line 1204, in _execute_context
[Thu Sep 17 02:46:49.226634 2020] [wsgi:error] [pid 10164:tid 139768390559488] [remote 180.69.96.107:0]     context = constructor(dialect, self, conn, *args)
[Thu Sep 17 02:46:49.226640 2020] [wsgi:error] [pid 10164:tid 139768390559488] [remote 180.69.96.107:0]   File "/usr/local/lib/python3.5/dist-packages/sqlalchemy/engine/default.py", line 801, in _init_compiled
[Thu Sep 17 02:46:49.226642 2020] [wsgi:error] [pid 10164:tid 139768390559488] [remote 180.69.96.107:0]     for grp, m in enumerate(parameters)
[Thu Sep 17 02:46:49.226647 2020] [wsgi:error] [pid 10164:tid 139768390559488] [remote 180.69.96.107:0]   File "/usr/local/lib/python3.5/dist-packages/sqlalchemy/engine/default.py", line 801, in <listcomp>
[Thu Sep 17 02:46:49.226649 2020] [wsgi:error] [pid 10164:tid 139768390559488] [remote 180.69.96.107:0]     for grp, m in enumerate(parameters)
[Thu Sep 17 02:46:49.226665 2020] [wsgi:error] [pid 10164:tid 139768390559488] [remote 180.69.96.107:0]   File "/usr/local/lib/python3.5/dist-packages/sqlalchemy/sql/compiler.py", line 696, in construct_params
[Thu Sep 17 02:46:49.226668 2020] [wsgi:error] [pid 10164:tid 139768390559488] [remote 180.69.96.107:0]     code="cd3x",
[Thu Sep 17 02:46:49.226683 2020] [wsgi:error] [pid 10164:tid 139768390559488] [remote 180.69.96.107:0] sqlalchemy.exc.InvalidRequestError: A value is required for bind parameter 'articleType' (Background on this error at: http://sqlalche.me/e/13/cd3x)
[Thu Sep 17 02:46:49.226690 2020] [wsgi:error] [pid 10164:tid 139768390559488] [remote 180.69.96.107:0] 
[Thu Sep 17 02:46:49.226693 2020] [wsgi:error] [pid 10164:tid 139768390559488] [remote 180.69.96.107:0] The above exception was the direct cause of the following exception:
[Thu Sep 17 02:46:49.226695 2020] [wsgi:error] [pid 10164:tid 139768390559488] [remote 180.69.96.107:0] 
[Thu Sep 17 02:46:49.226699 2020] [wsgi:error] [pid 10164:tid 139768390559488] [remote 180.69.96.107:0] Traceback (most recent call last):
[Thu Sep 17 02:46:49.226765 2020] [wsgi:error] [pid 10164:tid 139768390559488] [remote 180.69.96.107:0]   File "/usr/local/lib/python3.5/dist-packages/flask/app.py", line 2464, in __call__
[Thu Sep 17 02:46:49.226769 2020] [wsgi:error] [pid 10164:tid 139768390559488] [remote 180.69.96.107:0]     return self.wsgi_app(environ, start_response)
[Thu Sep 17 02:46:49.226775 2020] [wsgi:error] [pid 10164:tid 139768390559488] [remote 180.69.96.107:0]   File "/usr/local/lib/python3.5/dist-packages/flask/app.py", line 2450, in wsgi_app
[Thu Sep 17 02:46:49.226778 2020] [wsgi:error] [pid 10164:tid 139768390559488] [remote 180.69.96.107:0]     response = self.handle_exception(e)
[Thu Sep 17 02:46:49.226782 2020] [wsgi:error] [pid 10164:tid 139768390559488] [remote 180.69.96.107:0]   File "/usr/local/lib/python3.5/dist-packages/flask/app.py", line 1867, in handle_exception
[Thu Sep 17 02:46:49.226785 2020] [wsgi:error] [pid 10164:tid 139768390559488] [remote 180.69.96.107:0]     reraise(exc_type, exc_value, tb)
[Thu Sep 17 02:46:49.226789 2020] [wsgi:error] [pid 10164:tid 139768390559488] [remote 180.69.96.107:0]   File "/usr/local/lib/python3.5/dist-packages/flask/_compat.py", line 39, in reraise
[Thu Sep 17 02:46:49.226792 2020] [wsgi:error] [pid 10164:tid 139768390559488] [remote 180.69.96.107:0]     raise value
[Thu Sep 17 02:46:49.226796 2020] [wsgi:error] [pid 10164:tid 139768390559488] [remote 180.69.96.107:0]   File "/usr/local/lib/python3.5/dist-packages/flask/app.py", line 2447, in wsgi_app
[Thu Sep 17 02:46:49.226798 2020] [wsgi:error] [pid 10164:tid 139768390559488] [remote 180.69.96.107:0]     response = self.full_dispatch_request()
[Thu Sep 17 02:46:49.226809 2020] [wsgi:error] [pid 10164:tid 139768390559488] [remote 180.69.96.107:0]   File "/usr/local/lib/python3.5/dist-packages/flask/app.py", line 1952, in full_dispatch_request
[Thu Sep 17 02:46:49.226812 2020] [wsgi:error] [pid 10164:tid 139768390559488] [remote 180.69.96.107:0]     rv = self.handle_user_exception(e)
[Thu Sep 17 02:46:49.226817 2020] [wsgi:error] [pid 10164:tid 139768390559488] [remote 180.69.96.107:0]   File "/usr/local/lib/python3.5/dist-packages/flask/app.py", line 1821, in handle_user_exception
[Thu Sep 17 02:46:49.226819 2020] [wsgi:error] [pid 10164:tid 139768390559488] [remote 180.69.96.107:0]     reraise(exc_type, exc_value, tb)
[Thu Sep 17 02:46:49.226823 2020] [wsgi:error] [pid 10164:tid 139768390559488] [remote 180.69.96.107:0]   File "/usr/local/lib/python3.5/dist-packages/flask/_compat.py", line 39, in reraise
[Thu Sep 17 02:46:49.226825 2020] [wsgi:error] [pid 10164:tid 139768390559488] [remote 180.69.96.107:0]     raise value
[Thu Sep 17 02:46:49.226829 2020] [wsgi:error] [pid 10164:tid 139768390559488] [remote 180.69.96.107:0]   File "/usr/local/lib/python3.5/dist-packages/flask/app.py", line 1950, in full_dispatch_request
[Thu Sep 17 02:46:49.226832 2020] [wsgi:error] [pid 10164:tid 139768390559488] [remote 180.69.96.107:0]     rv = self.dispatch_request()
[Thu Sep 17 02:46:49.226836 2020] [wsgi:error] [pid 10164:tid 139768390559488] [remote 180.69.96.107:0]   File "/usr/local/lib/python3.5/dist-packages/flask/app.py", line 1936, in dispatch_request
[Thu Sep 17 02:46:49.226838 2020] [wsgi:error] [pid 10164:tid 139768390559488] [remote 180.69.96.107:0]     return self.view_functions[rule.endpoint](**req.view_args)
[Thu Sep 17 02:46:49.226842 2020] [wsgi:error] [pid 10164:tid 139768390559488] [remote 180.69.96.107:0]   File "/var/www/Appserver/flaskr/manage.py", line 91, in article
[Thu Sep 17 02:46:49.226844 2020] [wsgi:error] [pid 10164:tid 139768390559488] [remote 180.69.96.107:0]     """), article)
[Thu Sep 17 02:46:49.226848 2020] [wsgi:error] [pid 10164:tid 139768390559488] [remote 180.69.96.107:0]   File "/usr/local/lib/python3.5/dist-packages/sqlalchemy/engine/base.py", line 2237, in execute
[Thu Sep 17 02:46:49.226851 2020] [wsgi:error] [pid 10164:tid 139768390559488] [remote 180.69.96.107:0]     return connection.execute(statement, *multiparams, **params)
[Thu Sep 17 02:46:49.226855 2020] [wsgi:error] [pid 10164:tid 139768390559488] [remote 180.69.96.107:0]   File "/usr/local/lib/python3.5/dist-packages/sqlalchemy/engine/base.py", line 1011, in execute
[Thu Sep 17 02:46:49.226857 2020] [wsgi:error] [pid 10164:tid 139768390559488] [remote 180.69.96.107:0]     return meth(self, multiparams, params)
[Thu Sep 17 02:46:49.226861 2020] [wsgi:error] [pid 10164:tid 139768390559488] [remote 180.69.96.107:0]   File "/usr/local/lib/python3.5/dist-packages/sqlalchemy/sql/elements.py", line 298, in _execute_on_connection
[Thu Sep 17 02:46:49.226863 2020] [wsgi:error] [pid 10164:tid 139768390559488] [remote 180.69.96.107:0]     return connection._execute_clauseelement(self, multiparams, params)
[Thu Sep 17 02:46:49.226868 2020] [wsgi:error] [pid 10164:tid 139768390559488] [remote 180.69.96.107:0]   File "/usr/local/lib/python3.5/dist-packages/sqlalchemy/engine/base.py", line 1130, in _execute_clauseelement
[Thu Sep 17 02:46:49.226870 2020] [wsgi:error] [pid 10164:tid 139768390559488] [remote 180.69.96.107:0]     distilled_params,
[Thu Sep 17 02:46:49.226874 2020] [wsgi:error] [pid 10164:tid 139768390559488] [remote 180.69.96.107:0]   File "/usr/local/lib/python3.5/dist-packages/sqlalchemy/engine/base.py", line 1207, in _execute_context
[Thu Sep 17 02:46:49.226876 2020] [wsgi:error] [pid 10164:tid 139768390559488] [remote 180.69.96.107:0]     e, util.text_type(statement), parameters, None, None
[Thu Sep 17 02:46:49.226881 2020] [wsgi:error] [pid 10164:tid 139768390559488] [remote 180.69.96.107:0]   File "/usr/local/lib/python3.5/dist-packages/sqlalchemy/engine/base.py", line 1511, in _handle_dbapi_exception
[Thu Sep 17 02:46:49.226899 2020] [wsgi:error] [pid 10164:tid 139768390559488] [remote 180.69.96.107:0]     sqlalchemy_exception, with_traceback=exc_info[2], from_=e
[Thu Sep 17 02:46:49.226903 2020] [wsgi:error] [pid 10164:tid 139768390559488] [remote 180.69.96.107:0]   File "/usr/local/lib/python3.5/dist-packages/sqlalchemy/util/compat.py", line 182, in raise_
[Thu Sep 17 02:46:49.226905 2020] [wsgi:error] [pid 10164:tid 139768390559488] [remote 180.69.96.107:0]     raise exception
[Thu Sep 17 02:46:49.226910 2020] [wsgi:error] [pid 10164:tid 139768390559488] [remote 180.69.96.107:0]   File "/usr/local/lib/python3.5/dist-packages/sqlalchemy/engine/base.py", line 1204, in _execute_context
[Thu Sep 17 02:46:49.226912 2020] [wsgi:error] [pid 10164:tid 139768390559488] [remote 180.69.96.107:0]     context = constructor(dialect, self, conn, *args)
[Thu Sep 17 02:46:49.226916 2020] [wsgi:error] [pid 10164:tid 139768390559488] [remote 180.69.96.107:0]   File "/usr/local/lib/python3.5/dist-packages/sqlalchemy/engine/default.py", line 801, in _init_compiled
[Thu Sep 17 02:46:49.226918 2020] [wsgi:error] [pid 10164:tid 139768390559488] [remote 180.69.96.107:0]     for grp, m in enumerate(parameters)
[Thu Sep 17 02:46:49.226922 2020] [wsgi:error] [pid 10164:tid 139768390559488] [remote 180.69.96.107:0]   File "/usr/local/lib/python3.5/dist-packages/sqlalchemy/engine/default.py", line 801, in <listcomp>
[Thu Sep 17 02:46:49.226936 2020] [wsgi:error] [pid 10164:tid 139768390559488] [remote 180.69.96.107:0]     for grp, m in enumerate(parameters)
[Thu Sep 17 02:46:49.226941 2020] [wsgi:error] [pid 10164:tid 139768390559488] [remote 180.69.96.107:0]   File "/usr/local/lib/python3.5/dist-packages/sqlalchemy/sql/compiler.py", line 696, in construct_params
[Thu Sep 17 02:46:49.226943 2020] [wsgi:error] [pid 10164:tid 139768390559488] [remote 180.69.96.107:0]     code="cd3x",
[Thu Sep 17 02:46:49.226954 2020] [wsgi:error] [pid 10164:tid 139768390559488] [remote 180.69.96.107:0] sqlalchemy.exc.StatementError: (sqlalchemy.exc.InvalidRequestError) A value is required for bind parameter 'articleType'
[Thu Sep 17 02:46:49.226968 2020] [wsgi:error] [pid 10164:tid 139768390559488] [remote 180.69.96.107:0] [SQL: 
[Thu Sep 17 02:46:49.226970 2020] [wsgi:error] [pid 10164:tid 139768390559488] [remote 180.69.96.107:0]         INSERT INTO article (communityID, userID, isAnonymous, title, content)
[Thu Sep 17 02:46:49.226972 2020] [wsgi:error] [pid 10164:tid 139768390559488] [remote 180.69.96.107:0]         VALUES (%(articleType)s, %(userId)s, %(isAnonymous)s, %(title)s, %(content)s)
[Thu Sep 17 02:46:49.226974 2020] [wsgi:error] [pid 10164:tid 139768390559488] [remote 180.69.96.107:0]         ]
[Thu Sep 17 02:46:49.226975 2020] [wsgi:error] [pid 10164:tid 139768390559488] [remote 180.69.96.107:0] [parameters: [{'time': '2020/09/17 02:46:49'}]]
[Thu Sep 17 02:46:49.226977 2020] [wsgi:error] [pid 10164:tid 139768390559488] [remote 180.69.96.107:0] (Background on this error at: http://sqlalche.me/e/13/cd3x)
[Thu Sep 17 02:48:07.958740 2020] [wsgi:error] [pid 10309:tid 139768398960384] [remote 180.69.96.107:49244] mod_wsgi (pid=10309): Target WSGI script '/var/www/Appserver/flaskr/dodam.wsgi' cannot be loaded as Python module.
[Thu Sep 17 02:48:07.958787 2020] [wsgi:error] [pid 10309:tid 139768398960384] [remote 180.69.96.107:49244] mod_wsgi (pid=10309): Exception occurred processing WSGI script '/var/www/Appserver/flaskr/dodam.wsgi'.
[Thu Sep 17 02:48:07.958949 2020] [wsgi:error] [pid 10309:tid 139768398960384] [remote 180.69.96.107:49244] Traceback (most recent call last):
[Thu Sep 17 02:48:07.958969 2020] [wsgi:error] [pid 10309:tid 139768398960384] [remote 180.69.96.107:49244]   File "/var/www/Appserver/flaskr/dodam.wsgi", line 3, in <module>
[Thu Sep 17 02:48:07.958973 2020] [wsgi:error] [pid 10309:tid 139768398960384] [remote 180.69.96.107:49244]     hi
[Thu Sep 17 02:48:07.958985 2020] [wsgi:error] [pid 10309:tid 139768398960384] [remote 180.69.96.107:49244] NameError: name 'hi' is not defined
[Thu Sep 17 02:48:07.959342 2020] [wsgi:error] [pid 10309:tid 139768390559488] [remote 180.69.96.107:0] mod_wsgi (pid=10309): Target WSGI script '/var/www/Appserver/flaskr/dodam.wsgi' cannot be loaded as Python module.
[Thu Sep 17 02:48:07.959369 2020] [wsgi:error] [pid 10309:tid 139768390559488] [remote 180.69.96.107:0] mod_wsgi (pid=10309): Exception occurred processing WSGI script '/var/www/Appserver/flaskr/dodam.wsgi'.
[Thu Sep 17 02:48:07.959413 2020] [wsgi:error] [pid 10309:tid 139768390559488] [remote 180.69.96.107:0] Traceback (most recent call last):
[Thu Sep 17 02:48:07.959428 2020] [wsgi:error] [pid 10309:tid 139768390559488] [remote 180.69.96.107:0]   File "/var/www/Appserver/flaskr/dodam.wsgi", line 3, in <module>
[Thu Sep 17 02:48:07.959431 2020] [wsgi:error] [pid 10309:tid 139768390559488] [remote 180.69.96.107:0]     hi
[Thu Sep 17 02:48:07.959441 2020] [wsgi:error] [pid 10309:tid 139768390559488] [remote 180.69.96.107:0] NameError: name 'hi' is not defined
[Thu Sep 17 02:51:20.455700 2020] [wsgi:error] [pid 10440:tid 139768390559488] [remote 180.69.96.107:0] mod_wsgi (pid=10440): Exception occurred processing WSGI script '/var/www/Appserver/flaskr/dodam.wsgi'.
[Thu Sep 17 02:51:20.459129 2020] [wsgi:error] [pid 10440:tid 139768390559488] [remote 180.69.96.107:0] Traceback (most recent call last):
[Thu Sep 17 02:51:20.459176 2020] [wsgi:error] [pid 10440:tid 139768390559488] [remote 180.69.96.107:0]   File "/usr/local/lib/python3.5/dist-packages/sqlalchemy/engine/base.py", line 1204, in _execute_context
[Thu Sep 17 02:51:20.459181 2020] [wsgi:error] [pid 10440:tid 139768390559488] [remote 180.69.96.107:0]     context = constructor(dialect, self, conn, *args)
[Thu Sep 17 02:51:20.459187 2020] [wsgi:error] [pid 10440:tid 139768390559488] [remote 180.69.96.107:0]   File "/usr/local/lib/python3.5/dist-packages/sqlalchemy/engine/default.py", line 801, in _init_compiled
[Thu Sep 17 02:51:20.459189 2020] [wsgi:error] [pid 10440:tid 139768390559488] [remote 180.69.96.107:0]     for grp, m in enumerate(parameters)
[Thu Sep 17 02:51:20.459194 2020] [wsgi:error] [pid 10440:tid 139768390559488] [remote 180.69.96.107:0]   File "/usr/local/lib/python3.5/dist-packages/sqlalchemy/engine/default.py", line 801, in <listcomp>
[Thu Sep 17 02:51:20.459197 2020] [wsgi:error] [pid 10440:tid 139768390559488] [remote 180.69.96.107:0]     for grp, m in enumerate(parameters)
[Thu Sep 17 02:51:20.459202 2020] [wsgi:error] [pid 10440:tid 139768390559488] [remote 180.69.96.107:0]   File "/usr/local/lib/python3.5/dist-packages/sqlalchemy/sql/compiler.py", line 696, in construct_params
[Thu Sep 17 02:51:20.459216 2020] [wsgi:error] [pid 10440:tid 139768390559488] [remote 180.69.96.107:0]     code="cd3x",
[Thu Sep 17 02:51:20.459232 2020] [wsgi:error] [pid 10440:tid 139768390559488] [remote 180.69.96.107:0] sqlalchemy.exc.InvalidRequestError: A value is required for bind parameter 'articleType' (Background on this error at: http://sqlalche.me/e/13/cd3x)
[Thu Sep 17 02:51:20.459240 2020] [wsgi:error] [pid 10440:tid 139768390559488] [remote 180.69.96.107:0] 
[Thu Sep 17 02:51:20.459243 2020] [wsgi:error] [pid 10440:tid 139768390559488] [remote 180.69.96.107:0] The above exception was the direct cause of the following exception:
[Thu Sep 17 02:51:20.459245 2020] [wsgi:error] [pid 10440:tid 139768390559488] [remote 180.69.96.107:0] 
[Thu Sep 17 02:51:20.459250 2020] [wsgi:error] [pid 10440:tid 139768390559488] [remote 180.69.96.107:0] Traceback (most recent call last):
[Thu Sep 17 02:51:20.459303 2020] [wsgi:error] [pid 10440:tid 139768390559488] [remote 180.69.96.107:0]   File "/usr/local/lib/python3.5/dist-packages/flask/app.py", line 2464, in __call__
[Thu Sep 17 02:51:20.459306 2020] [wsgi:error] [pid 10440:tid 139768390559488] [remote 180.69.96.107:0]     return self.wsgi_app(environ, start_response)
[Thu Sep 17 02:51:20.459314 2020] [wsgi:error] [pid 10440:tid 139768390559488] [remote 180.69.96.107:0]   File "/usr/local/lib/python3.5/dist-packages/flask/app.py", line 2450, in wsgi_app
[Thu Sep 17 02:51:20.459317 2020] [wsgi:error] [pid 10440:tid 139768390559488] [remote 180.69.96.107:0]     response = self.handle_exception(e)
[Thu Sep 17 02:51:20.459329 2020] [wsgi:error] [pid 10440:tid 139768390559488] [remote 180.69.96.107:0]   File "/usr/local/lib/python3.5/dist-packages/flask/app.py", line 1867, in handle_exception
[Thu Sep 17 02:51:20.459332 2020] [wsgi:error] [pid 10440:tid 139768390559488] [remote 180.69.96.107:0]     reraise(exc_type, exc_value, tb)
[Thu Sep 17 02:51:20.459336 2020] [wsgi:error] [pid 10440:tid 139768390559488] [remote 180.69.96.107:0]   File "/usr/local/lib/python3.5/dist-packages/flask/_compat.py", line 39, in reraise
[Thu Sep 17 02:51:20.459338 2020] [wsgi:error] [pid 10440:tid 139768390559488] [remote 180.69.96.107:0]     raise value
[Thu Sep 17 02:51:20.459342 2020] [wsgi:error] [pid 10440:tid 139768390559488] [remote 180.69.96.107:0]   File "/usr/local/lib/python3.5/dist-packages/flask/app.py", line 2447, in wsgi_app
[Thu Sep 17 02:51:20.459344 2020] [wsgi:error] [pid 10440:tid 139768390559488] [remote 180.69.96.107:0]     response = self.full_dispatch_request()
[Thu Sep 17 02:51:20.459348 2020] [wsgi:error] [pid 10440:tid 139768390559488] [remote 180.69.96.107:0]   File "/usr/local/lib/python3.5/dist-packages/flask/app.py", line 1952, in full_dispatch_request
[Thu Sep 17 02:51:20.459350 2020] [wsgi:error] [pid 10440:tid 139768390559488] [remote 180.69.96.107:0]     rv = self.handle_user_exception(e)
[Thu Sep 17 02:51:20.459354 2020] [wsgi:error] [pid 10440:tid 139768390559488] [remote 180.69.96.107:0]   File "/usr/local/lib/python3.5/dist-packages/flask/app.py", line 1821, in handle_user_exception
[Thu Sep 17 02:51:20.459356 2020] [wsgi:error] [pid 10440:tid 139768390559488] [remote 180.69.96.107:0]     reraise(exc_type, exc_value, tb)
[Thu Sep 17 02:51:20.459360 2020] [wsgi:error] [pid 10440:tid 139768390559488] [remote 180.69.96.107:0]   File "/usr/local/lib/python3.5/dist-packages/flask/_compat.py", line 39, in reraise
[Thu Sep 17 02:51:20.459362 2020] [wsgi:error] [pid 10440:tid 139768390559488] [remote 180.69.96.107:0]     raise value
[Thu Sep 17 02:51:20.459366 2020] [wsgi:error] [pid 10440:tid 139768390559488] [remote 180.69.96.107:0]   File "/usr/local/lib/python3.5/dist-packages/flask/app.py", line 1950, in full_dispatch_request
[Thu Sep 17 02:51:20.459368 2020] [wsgi:error] [pid 10440:tid 139768390559488] [remote 180.69.96.107:0]     rv = self.dispatch_request()
[Thu Sep 17 02:51:20.459372 2020] [wsgi:error] [pid 10440:tid 139768390559488] [remote 180.69.96.107:0]   File "/usr/local/lib/python3.5/dist-packages/flask/app.py", line 1936, in dispatch_request
[Thu Sep 17 02:51:20.459375 2020] [wsgi:error] [pid 10440:tid 139768390559488] [remote 180.69.96.107:0]     return self.view_functions[rule.endpoint](**req.view_args)
[Thu Sep 17 02:51:20.459379 2020] [wsgi:error] [pid 10440:tid 139768390559488] [remote 180.69.96.107:0]   File "/var/www/Appserver/flaskr/manage.py", line 91, in article
[Thu Sep 17 02:51:20.459381 2020] [wsgi:error] [pid 10440:tid 139768390559488] [remote 180.69.96.107:0]     """), article)
[Thu Sep 17 02:51:20.459385 2020] [wsgi:error] [pid 10440:tid 139768390559488] [remote 180.69.96.107:0]   File "/usr/local/lib/python3.5/dist-packages/sqlalchemy/engine/base.py", line 2237, in execute
[Thu Sep 17 02:51:20.459387 2020] [wsgi:error] [pid 10440:tid 139768390559488] [remote 180.69.96.107:0]     return connection.execute(statement, *multiparams, **params)
[Thu Sep 17 02:51:20.459391 2020] [wsgi:error] [pid 10440:tid 139768390559488] [remote 180.69.96.107:0]   File "/usr/local/lib/python3.5/dist-packages/sqlalchemy/engine/base.py", line 1011, in execute
[Thu Sep 17 02:51:20.459405 2020] [wsgi:error] [pid 10440:tid 139768390559488] [remote 180.69.96.107:0]     return meth(self, multiparams, params)
[Thu Sep 17 02:51:20.459410 2020] [wsgi:error] [pid 10440:tid 139768390559488] [remote 180.69.96.107:0]   File "/usr/local/lib/python3.5/dist-packages/sqlalchemy/sql/elements.py", line 298, in _execute_on_connection
[Thu Sep 17 02:51:20.459412 2020] [wsgi:error] [pid 10440:tid 139768390559488] [remote 180.69.96.107:0]     return connection._execute_clauseelement(self, multiparams, params)
[Thu Sep 17 02:51:20.459420 2020] [wsgi:error] [pid 10440:tid 139768390559488] [remote 180.69.96.107:0]   File "/usr/local/lib/python3.5/dist-packages/sqlalchemy/engine/base.py", line 1130, in _execute_clauseelement
[Thu Sep 17 02:51:20.459422 2020] [wsgi:error] [pid 10440:tid 139768390559488] [remote 180.69.96.107:0]     distilled_params,
[Thu Sep 17 02:51:20.459426 2020] [wsgi:error] [pid 10440:tid 139768390559488] [remote 180.69.96.107:0]   File "/usr/local/lib/python3.5/dist-packages/sqlalchemy/engine/base.py", line 1207, in _execute_context
[Thu Sep 17 02:51:20.459429 2020] [wsgi:error] [pid 10440:tid 139768390559488] [remote 180.69.96.107:0]     e, util.text_type(statement), parameters, None, None
[Thu Sep 17 02:51:20.459445 2020] [wsgi:error] [pid 10440:tid 139768390559488] [remote 180.69.96.107:0]   File "/usr/local/lib/python3.5/dist-packages/sqlalchemy/engine/base.py", line 1511, in _handle_dbapi_exception
[Thu Sep 17 02:51:20.459447 2020] [wsgi:error] [pid 10440:tid 139768390559488] [remote 180.69.96.107:0]     sqlalchemy_exception, with_traceback=exc_info[2], from_=e
[Thu Sep 17 02:51:20.459452 2020] [wsgi:error] [pid 10440:tid 139768390559488] [remote 180.69.96.107:0]   File "/usr/local/lib/python3.5/dist-packages/sqlalchemy/util/compat.py", line 182, in raise_
[Thu Sep 17 02:51:20.459454 2020] [wsgi:error] [pid 10440:tid 139768390559488] [remote 180.69.96.107:0]     raise exception
[Thu Sep 17 02:51:20.459458 2020] [wsgi:error] [pid 10440:tid 139768390559488] [remote 180.69.96.107:0]   File "/usr/local/lib/python3.5/dist-packages/sqlalchemy/engine/base.py", line 1204, in _execute_context
[Thu Sep 17 02:51:20.459461 2020] [wsgi:error] [pid 10440:tid 139768390559488] [remote 180.69.96.107:0]     context = constructor(dialect, self, conn, *args)
[Thu Sep 17 02:51:20.459465 2020] [wsgi:error] [pid 10440:tid 139768390559488] [remote 180.69.96.107:0]   File "/usr/local/lib/python3.5/dist-packages/sqlalchemy/engine/default.py", line 801, in _init_compiled
[Thu Sep 17 02:51:20.459467 2020] [wsgi:error] [pid 10440:tid 139768390559488] [remote 180.69.96.107:0]     for grp, m in enumerate(parameters)
[Thu Sep 17 02:51:20.459472 2020] [wsgi:error] [pid 10440:tid 139768390559488] [remote 180.69.96.107:0]   File "/usr/local/lib/python3.5/dist-packages/sqlalchemy/engine/default.py", line 801, in <listcomp>
[Thu Sep 17 02:51:20.459474 2020] [wsgi:error] [pid 10440:tid 139768390559488] [remote 180.69.96.107:0]     for grp, m in enumerate(parameters)
[Thu Sep 17 02:51:20.459478 2020] [wsgi:error] [pid 10440:tid 139768390559488] [remote 180.69.96.107:0]   File "/usr/local/lib/python3.5/dist-packages/sqlalchemy/sql/compiler.py", line 696, in construct_params
[Thu Sep 17 02:51:20.459481 2020] [wsgi:error] [pid 10440:tid 139768390559488] [remote 180.69.96.107:0]     code="cd3x",
[Thu Sep 17 02:51:20.459493 2020] [wsgi:error] [pid 10440:tid 139768390559488] [remote 180.69.96.107:0] sqlalchemy.exc.StatementError: (sqlalchemy.exc.InvalidRequestError) A value is required for bind parameter 'articleType'
[Thu Sep 17 02:51:20.459496 2020] [wsgi:error] [pid 10440:tid 139768390559488] [remote 180.69.96.107:0] [SQL: 
[Thu Sep 17 02:51:20.459498 2020] [wsgi:error] [pid 10440:tid 139768390559488] [remote 180.69.96.107:0]         INSERT INTO article (communityID, userID, isAnonymous, title, content)
[Thu Sep 17 02:51:20.459500 2020] [wsgi:error] [pid 10440:tid 139768390559488] [remote 180.69.96.107:0]         VALUES (%(articleType)s, %(userId)s, %(isAnonymous)s, %(title)s, %(content)s)
[Thu Sep 17 02:51:20.459502 2020] [wsgi:error] [pid 10440:tid 139768390559488] [remote 180.69.96.107:0]         ]
[Thu Sep 17 02:51:20.459503 2020] [wsgi:error] [pid 10440:tid 139768390559488] [remote 180.69.96.107:0] [parameters: [{'time': '2020/09/17 02:51:20'}]]
[Thu Sep 17 02:51:20.459517 2020] [wsgi:error] [pid 10440:tid 139768390559488] [remote 180.69.96.107:0] (Background on this error at: http://sqlalche.me/e/13/cd3x)
[Thu Sep 17 02:54:44.135663 2020] [wsgi:error] [pid 10440:tid 139768398960384] [remote 180.69.96.107:49244] mod_wsgi (pid=10440): Exception occurred processing WSGI script '/var/www/Appserver/flaskr/dodam.wsgi'.
[Thu Sep 17 02:54:44.136022 2020] [wsgi:error] [pid 10440:tid 139768398960384] [remote 180.69.96.107:49244] Traceback (most recent call last):
[Thu Sep 17 02:54:44.136057 2020] [wsgi:error] [pid 10440:tid 139768398960384] [remote 180.69.96.107:49244]   File "/usr/local/lib/python3.5/dist-packages/sqlalchemy/engine/base.py", line 1204, in _execute_context
[Thu Sep 17 02:54:44.136061 2020] [wsgi:error] [pid 10440:tid 139768398960384] [remote 180.69.96.107:49244]     context = constructor(dialect, self, conn, *args)
[Thu Sep 17 02:54:44.136066 2020] [wsgi:error] [pid 10440:tid 139768398960384] [remote 180.69.96.107:49244]   File "/usr/local/lib/python3.5/dist-packages/sqlalchemy/engine/default.py", line 801, in _init_compiled
[Thu Sep 17 02:54:44.136068 2020] [wsgi:error] [pid 10440:tid 139768398960384] [remote 180.69.96.107:49244]     for grp, m in enumerate(parameters)
[Thu Sep 17 02:54:44.136073 2020] [wsgi:error] [pid 10440:tid 139768398960384] [remote 180.69.96.107:49244]   File "/usr/local/lib/python3.5/dist-packages/sqlalchemy/engine/default.py", line 801, in <listcomp>
[Thu Sep 17 02:54:44.136075 2020] [wsgi:error] [pid 10440:tid 139768398960384] [remote 180.69.96.107:49244]     for grp, m in enumerate(parameters)
[Thu Sep 17 02:54:44.136079 2020] [wsgi:error] [pid 10440:tid 139768398960384] [remote 180.69.96.107:49244]   File "/usr/local/lib/python3.5/dist-packages/sqlalchemy/sql/compiler.py", line 696, in construct_params
[Thu Sep 17 02:54:44.136081 2020] [wsgi:error] [pid 10440:tid 139768398960384] [remote 180.69.96.107:49244]     code="cd3x",
[Thu Sep 17 02:54:44.136094 2020] [wsgi:error] [pid 10440:tid 139768398960384] [remote 180.69.96.107:49244] sqlalchemy.exc.InvalidRequestError: A value is required for bind parameter 'articleType' (Background on this error at: http://sqlalche.me/e/13/cd3x)
[Thu Sep 17 02:54:44.136114 2020] [wsgi:error] [pid 10440:tid 139768398960384] [remote 180.69.96.107:49244] 
[Thu Sep 17 02:54:44.136117 2020] [wsgi:error] [pid 10440:tid 139768398960384] [remote 180.69.96.107:49244] The above exception was the direct cause of the following exception:
[Thu Sep 17 02:54:44.136118 2020] [wsgi:error] [pid 10440:tid 139768398960384] [remote 180.69.96.107:49244] 
[Thu Sep 17 02:54:44.136122 2020] [wsgi:error] [pid 10440:tid 139768398960384] [remote 180.69.96.107:49244] Traceback (most recent call last):
[Thu Sep 17 02:54:44.136171 2020] [wsgi:error] [pid 10440:tid 139768398960384] [remote 180.69.96.107:49244]   File "/usr/local/lib/python3.5/dist-packages/flask/app.py", line 2464, in __call__
[Thu Sep 17 02:54:44.136174 2020] [wsgi:error] [pid 10440:tid 139768398960384] [remote 180.69.96.107:49244]     return self.wsgi_app(environ, start_response)
[Thu Sep 17 02:54:44.136178 2020] [wsgi:error] [pid 10440:tid 139768398960384] [remote 180.69.96.107:49244]   File "/usr/local/lib/python3.5/dist-packages/flask/app.py", line 2450, in wsgi_app
[Thu Sep 17 02:54:44.136180 2020] [wsgi:error] [pid 10440:tid 139768398960384] [remote 180.69.96.107:49244]     response = self.handle_exception(e)
[Thu Sep 17 02:54:44.136183 2020] [wsgi:error] [pid 10440:tid 139768398960384] [remote 180.69.96.107:49244]   File "/usr/local/lib/python3.5/dist-packages/flask/app.py", line 1867, in handle_exception
[Thu Sep 17 02:54:44.136185 2020] [wsgi:error] [pid 10440:tid 139768398960384] [remote 180.69.96.107:49244]     reraise(exc_type, exc_value, tb)
[Thu Sep 17 02:54:44.136189 2020] [wsgi:error] [pid 10440:tid 139768398960384] [remote 180.69.96.107:49244]   File "/usr/local/lib/python3.5/dist-packages/flask/_compat.py", line 39, in reraise
[Thu Sep 17 02:54:44.136191 2020] [wsgi:error] [pid 10440:tid 139768398960384] [remote 180.69.96.107:49244]     raise value
[Thu Sep 17 02:54:44.136194 2020] [wsgi:error] [pid 10440:tid 139768398960384] [remote 180.69.96.107:49244]   File "/usr/local/lib/python3.5/dist-packages/flask/app.py", line 2447, in wsgi_app
[Thu Sep 17 02:54:44.136196 2020] [wsgi:error] [pid 10440:tid 139768398960384] [remote 180.69.96.107:49244]     response = self.full_dispatch_request()
[Thu Sep 17 02:54:44.136205 2020] [wsgi:error] [pid 10440:tid 139768398960384] [remote 180.69.96.107:49244]   File "/usr/local/lib/python3.5/dist-packages/flask/app.py", line 1952, in full_dispatch_request
[Thu Sep 17 02:54:44.136207 2020] [wsgi:error] [pid 10440:tid 139768398960384] [remote 180.69.96.107:49244]     rv = self.handle_user_exception(e)
[Thu Sep 17 02:54:44.136211 2020] [wsgi:error] [pid 10440:tid 139768398960384] [remote 180.69.96.107:49244]   File "/usr/local/lib/python3.5/dist-packages/flask/app.py", line 1821, in handle_user_exception
[Thu Sep 17 02:54:44.136212 2020] [wsgi:error] [pid 10440:tid 139768398960384] [remote 180.69.96.107:49244]     reraise(exc_type, exc_value, tb)
[Thu Sep 17 02:54:44.136216 2020] [wsgi:error] [pid 10440:tid 139768398960384] [remote 180.69.96.107:49244]   File "/usr/local/lib/python3.5/dist-packages/flask/_compat.py", line 39, in reraise
[Thu Sep 17 02:54:44.136218 2020] [wsgi:error] [pid 10440:tid 139768398960384] [remote 180.69.96.107:49244]     raise value
[Thu Sep 17 02:54:44.136221 2020] [wsgi:error] [pid 10440:tid 139768398960384] [remote 180.69.96.107:49244]   File "/usr/local/lib/python3.5/dist-packages/flask/app.py", line 1950, in full_dispatch_request
[Thu Sep 17 02:54:44.136223 2020] [wsgi:error] [pid 10440:tid 139768398960384] [remote 180.69.96.107:49244]     rv = self.dispatch_request()
[Thu Sep 17 02:54:44.136228 2020] [wsgi:error] [pid 10440:tid 139768398960384] [remote 180.69.96.107:49244]   File "/usr/local/lib/python3.5/dist-packages/flask/app.py", line 1936, in dispatch_request
[Thu Sep 17 02:54:44.136230 2020] [wsgi:error] [pid 10440:tid 139768398960384] [remote 180.69.96.107:49244]     return self.view_functions[rule.endpoint](**req.view_args)
[Thu Sep 17 02:54:44.136234 2020] [wsgi:error] [pid 10440:tid 139768398960384] [remote 180.69.96.107:49244]   File "/var/www/Appserver/flaskr/manage.py", line 91, in article
[Thu Sep 17 02:54:44.136235 2020] [wsgi:error] [pid 10440:tid 139768398960384] [remote 180.69.96.107:49244]     """), article)
[Thu Sep 17 02:54:44.136239 2020] [wsgi:error] [pid 10440:tid 139768398960384] [remote 180.69.96.107:49244]   File "/usr/local/lib/python3.5/dist-packages/sqlalchemy/engine/base.py", line 2237, in execute
[Thu Sep 17 02:54:44.136241 2020] [wsgi:error] [pid 10440:tid 139768398960384] [remote 180.69.96.107:49244]     return connection.execute(statement, *multiparams, **params)
[Thu Sep 17 02:54:44.136245 2020] [wsgi:error] [pid 10440:tid 139768398960384] [remote 180.69.96.107:49244]   File "/usr/local/lib/python3.5/dist-packages/sqlalchemy/engine/base.py", line 1011, in execute
[Thu Sep 17 02:54:44.136247 2020] [wsgi:error] [pid 10440:tid 139768398960384] [remote 180.69.96.107:49244]     return meth(self, multiparams, params)
[Thu Sep 17 02:54:44.136251 2020] [wsgi:error] [pid 10440:tid 139768398960384] [remote 180.69.96.107:49244]   File "/usr/local/lib/python3.5/dist-packages/sqlalchemy/sql/elements.py", line 298, in _execute_on_connection
[Thu Sep 17 02:54:44.136253 2020] [wsgi:error] [pid 10440:tid 139768398960384] [remote 180.69.96.107:49244]     return connection._execute_clauseelement(self, multiparams, params)
[Thu Sep 17 02:54:44.136256 2020] [wsgi:error] [pid 10440:tid 139768398960384] [remote 180.69.96.107:49244]   File "/usr/local/lib/python3.5/dist-packages/sqlalchemy/engine/base.py", line 1130, in _execute_clauseelement
[Thu Sep 17 02:54:44.136258 2020] [wsgi:error] [pid 10440:tid 139768398960384] [remote 180.69.96.107:49244]     distilled_params,
[Thu Sep 17 02:54:44.136262 2020] [wsgi:error] [pid 10440:tid 139768398960384] [remote 180.69.96.107:49244]   File "/usr/local/lib/python3.5/dist-packages/sqlalchemy/engine/base.py", line 1207, in _execute_context
[Thu Sep 17 02:54:44.136264 2020] [wsgi:error] [pid 10440:tid 139768398960384] [remote 180.69.96.107:49244]     e, util.text_type(statement), parameters, None, None
[Thu Sep 17 02:54:44.136268 2020] [wsgi:error] [pid 10440:tid 139768398960384] [remote 180.69.96.107:49244]   File "/usr/local/lib/python3.5/dist-packages/sqlalchemy/engine/base.py", line 1511, in _handle_dbapi_exception
[Thu Sep 17 02:54:44.136272 2020] [wsgi:error] [pid 10440:tid 139768398960384] [remote 180.69.96.107:49244]     sqlalchemy_exception, with_traceback=exc_info[2], from_=e
[Thu Sep 17 02:54:44.136276 2020] [wsgi:error] [pid 10440:tid 139768398960384] [remote 180.69.96.107:49244]   File "/usr/local/lib/python3.5/dist-packages/sqlalchemy/util/compat.py", line 182, in raise_
[Thu Sep 17 02:54:44.136278 2020] [wsgi:error] [pid 10440:tid 139768398960384] [remote 180.69.96.107:49244]     raise exception
[Thu Sep 17 02:54:44.136282 2020] [wsgi:error] [pid 10440:tid 139768398960384] [remote 180.69.96.107:49244]   File "/usr/local/lib/python3.5/dist-packages/sqlalchemy/engine/base.py", line 1204, in _execute_context
[Thu Sep 17 02:54:44.136284 2020] [wsgi:error] [pid 10440:tid 139768398960384] [remote 180.69.96.107:49244]     context = constructor(dialect, self, conn, *args)
[Thu Sep 17 02:54:44.136287 2020] [wsgi:error] [pid 10440:tid 139768398960384] [remote 180.69.96.107:49244]   File "/usr/local/lib/python3.5/dist-packages/sqlalchemy/engine/default.py", line 801, in _init_compiled
[Thu Sep 17 02:54:44.136289 2020] [wsgi:error] [pid 10440:tid 139768398960384] [remote 180.69.96.107:49244]     for grp, m in enumerate(parameters)
[Thu Sep 17 02:54:44.136293 2020] [wsgi:error] [pid 10440:tid 139768398960384] [remote 180.69.96.107:49244]   File "/usr/local/lib/python3.5/dist-packages/sqlalchemy/engine/default.py", line 801, in <listcomp>
[Thu Sep 17 02:54:44.136295 2020] [wsgi:error] [pid 10440:tid 139768398960384] [remote 180.69.96.107:49244]     for grp, m in enumerate(parameters)
[Thu Sep 17 02:54:44.136298 2020] [wsgi:error] [pid 10440:tid 139768398960384] [remote 180.69.96.107:49244]   File "/usr/local/lib/python3.5/dist-packages/sqlalchemy/sql/compiler.py", line 696, in construct_params
[Thu Sep 17 02:54:44.136300 2020] [wsgi:error] [pid 10440:tid 139768398960384] [remote 180.69.96.107:49244]     code="cd3x",
[Thu Sep 17 02:54:44.136312 2020] [wsgi:error] [pid 10440:tid 139768398960384] [remote 180.69.96.107:49244] sqlalchemy.exc.StatementError: (sqlalchemy.exc.InvalidRequestError) A value is required for bind parameter 'articleType'
[Thu Sep 17 02:54:44.136327 2020] [wsgi:error] [pid 10440:tid 139768398960384] [remote 180.69.96.107:49244] [SQL: 
[Thu Sep 17 02:54:44.136329 2020] [wsgi:error] [pid 10440:tid 139768398960384] [remote 180.69.96.107:49244]         INSERT INTO article (communityID, userID, isAnonymous, title, content)
[Thu Sep 17 02:54:44.136330 2020] [wsgi:error] [pid 10440:tid 139768398960384] [remote 180.69.96.107:49244]         VALUES (%(articleType)s, %(userId)s, %(isAnonymous)s, %(title)s, %(content)s)
[Thu Sep 17 02:54:44.136332 2020] [wsgi:error] [pid 10440:tid 139768398960384] [remote 180.69.96.107:49244]         ]
[Thu Sep 17 02:54:44.136334 2020] [wsgi:error] [pid 10440:tid 139768398960384] [remote 180.69.96.107:49244] [parameters: [{'time': '2020/09/17 02:54:44'}]]
[Thu Sep 17 02:54:44.136336 2020] [wsgi:error] [pid 10440:tid 139768398960384] [remote 180.69.96.107:49244] (Background on this error at: http://sqlalche.me/e/13/cd3x)
[Thu Sep 17 07:57:55.339575 2020] [wsgi:error] [pid 22498:tid 140421377312512] None
[Thu Sep 17 07:58:04.248017 2020] [wsgi:error] [pid 22498:tid 140421343733504] (20, 1, '\xeb\xa7\x8e\xec\x9d\x80 \xeb\x8b\xa4 \xec\x9d\xb4\xec\x9b\x83 \xeb\xb9\x84\xeb\x91\x98\xea\xb8\xb0, \xeb\x82\xb4 \xea\xb9\x8c\xeb\x8b\xad\xec\x9e\x85\xeb\x8b\x88\xeb\x8b\xa4. \xed\x94\xbc\xec\x96\xb4\xeb\x82\x98\xeb\x93\xaf\xec\x9d\xb4 \xec\x95\xa0\xea\xb8\xb0 \xec\x9a\xb0\xeb\x8a\x94 \xeb\x90\x9c \xeb\xac\xb4\xec\x97\x87\xec\x9d\xb8\xec\xa7\x80 \xed\x95\x98\xeb\x82\x98\xec\x97\x90 \xec\x82\xac\xeb\x9e\x91\xea\xb3\xbc \xed\x97\xa4\xec\x9d\xbc \xeb\xb4\x85\xeb\x8b\x88\xeb\x8b\xa4.\\n\\n\xec\x95\x84\xeb\xa6\x84\xeb\x8b\xa4\xec\x9a\xb4 \xec\x8b\x9c\xec\x9d\xb8\xec\x9d\x98 \xeb\x8f\x99\xea\xb2\xbd\xea\xb3\xbc \xeb\x8b\xb9\xec\x8b\xa0\xec\x9d\x80 \xeb\x82\x98\xec\x9d\x98 \xec\x9d\xb4\xeb\xa6\x84\xec\x9e\x90\xeb\xa5\xbc \xed\x8c\x8c\xeb\x9e\x80 \xec\x98\xa4\xeb\x8a\x94 \xeb\xb3\xb4\xea\xb3\xa0, \xeb\xb4\x85\xeb\x8b\x88\xeb\x8b\xa4. \xeb\x8b\xa4 \xeb\xb3\x84 \xeb\xaa\xbb \xeb\xb6\x81\xea\xb0\x84\xeb\x8f\x84\xec\x97\x90 \xec\x95\x84\xec\xb9\xa8\xec\x9d\xb4 \xed\x95\x98\xeb\x82\x98\xec\x9d\x98 \xec\x9a\xb0\xeb\x8a\x94 \xed\x95\x98\xeb\x82\x98\xec\x97\x90 \xea\xb3\x84\xec\x8b\xad\xeb\x8b\x88\xeb\x8b\xa4. \xec\x9c\x84\xec\x97\x90 \xec\x9d\xb4\xec\xa0\x9c \xec\x86\x8c\xed\x95\x99\xea\xb5\x90 \xed\x95\x98\xeb\x82\x98\xec\x97\x90 \xeb\xb4\x84\xec\x9d\xb4 \xeb\x90\x9c \xec\x9d\xb4\xeb\xa6\x84\xea\xb3\xbc, \xec\x8b\x9c\xec\x9d\xb8\xec\x9d\x98 \xec\x9a\xb0\xeb\x8a\x94 \xeb\xb4\x85\xeb\x8b\x88\xeb\x8b\xa4. \xea\xb7\xb8\xeb\xa6\xac\xea\xb3\xa0 \xea\xb0\x95\xec\x95\x84\xec\xa7\x80, \xeb\x85\xb8\xec\x83\x88, \xea\xb1\xb0\xec\x99\xb8\xeb\x8b\xa4.', '\xeb\xa7\x8e\xec\x9d\x80 \xeb\x8b\xa4 \xec\x9d\xb4\xec\x9b\x83 \xeb\xb9\x84\xeb\x91\x98\xea\xb8\xb0, \xeb\x82\xb4 \xea\xb9\x8c\xeb\x8b\xad\xec\x9e\x85\xeb\x8b\x88\xeb\x8b\xa4. \xed\x94\xbc\xec\x96\xb4\xeb\x82\x98\xeb\x93\xaf\xec\x9d\xb4 \xec\x95\xa0\xea\xb8\xb0 \xec\x9a\xb0\xeb\x8a\x94 \xeb\x90\x9c \xeb\xac\xb4\xec\x97\x87\xec\x9d\xb8\xec\xa7\x80', 10, 2, 1, None, 'hankyul')
[Thu Sep 17 08:34:47.687428 2020] [wsgi:error] [pid 22498:tid 140421343733504] [remote 180.69.96.107:50540] mod_wsgi (pid=22498): Exception occurred processing WSGI script '/var/www/Appserver/flaskr/dodam.wsgi'.
[Thu Sep 17 08:34:47.688469 2020] [wsgi:error] [pid 22498:tid 140421343733504] [remote 180.69.96.107:50540] Traceback (most recent call last):
[Thu Sep 17 08:34:47.688530 2020] [wsgi:error] [pid 22498:tid 140421343733504] [remote 180.69.96.107:50540]   File "/usr/local/lib/python3.5/dist-packages/flask/app.py", line 2464, in __call__
[Thu Sep 17 08:34:47.688535 2020] [wsgi:error] [pid 22498:tid 140421343733504] [remote 180.69.96.107:50540]     return self.wsgi_app(environ, start_response)
[Thu Sep 17 08:34:47.688541 2020] [wsgi:error] [pid 22498:tid 140421343733504] [remote 180.69.96.107:50540]   File "/usr/local/lib/python3.5/dist-packages/flask/app.py", line 2450, in wsgi_app
[Thu Sep 17 08:34:47.688544 2020] [wsgi:error] [pid 22498:tid 140421343733504] [remote 180.69.96.107:50540]     response = self.handle_exception(e)
[Thu Sep 17 08:34:47.688549 2020] [wsgi:error] [pid 22498:tid 140421343733504] [remote 180.69.96.107:50540]   File "/usr/local/lib/python3.5/dist-packages/flask/app.py", line 1867, in handle_exception
[Thu Sep 17 08:34:47.688552 2020] [wsgi:error] [pid 22498:tid 140421343733504] [remote 180.69.96.107:50540]     reraise(exc_type, exc_value, tb)
[Thu Sep 17 08:34:47.688559 2020] [wsgi:error] [pid 22498:tid 140421343733504] [remote 180.69.96.107:50540]   File "/usr/local/lib/python3.5/dist-packages/flask/_compat.py", line 39, in reraise
[Thu Sep 17 08:34:47.688562 2020] [wsgi:error] [pid 22498:tid 140421343733504] [remote 180.69.96.107:50540]     raise value
[Thu Sep 17 08:34:47.688567 2020] [wsgi:error] [pid 22498:tid 140421343733504] [remote 180.69.96.107:50540]   File "/usr/local/lib/python3.5/dist-packages/flask/app.py", line 2447, in wsgi_app
[Thu Sep 17 08:34:47.688570 2020] [wsgi:error] [pid 22498:tid 140421343733504] [remote 180.69.96.107:50540]     response = self.full_dispatch_request()
[Thu Sep 17 08:34:47.688586 2020] [wsgi:error] [pid 22498:tid 140421343733504] [remote 180.69.96.107:50540]   File "/usr/local/lib/python3.5/dist-packages/flask/app.py", line 1953, in full_dispatch_request
[Thu Sep 17 08:34:47.688589 2020] [wsgi:error] [pid 22498:tid 140421343733504] [remote 180.69.96.107:50540]     return self.finalize_request(rv)
[Thu Sep 17 08:34:47.688608 2020] [wsgi:error] [pid 22498:tid 140421343733504] [remote 180.69.96.107:50540]   File "/usr/local/lib/python3.5/dist-packages/flask/app.py", line 1968, in finalize_request
[Thu Sep 17 08:34:47.688610 2020] [wsgi:error] [pid 22498:tid 140421343733504] [remote 180.69.96.107:50540]     response = self.make_response(rv)
[Thu Sep 17 08:34:47.688626 2020] [wsgi:error] [pid 22498:tid 140421343733504] [remote 180.69.96.107:50540]   File "/usr/local/lib/python3.5/dist-packages/flask/app.py", line 2098, in make_response
[Thu Sep 17 08:34:47.688637 2020] [wsgi:error] [pid 22498:tid 140421343733504] [remote 180.69.96.107:50540]     "The view function did not return a valid response. The"
[Thu Sep 17 08:34:47.688655 2020] [wsgi:error] [pid 22498:tid 140421343733504] [remote 180.69.96.107:50540] TypeError: The view function did not return a valid response. The function either returned None or ended without a return statement.
[Thu Sep 17 10:41:25.245815 2020] [wsgi:error] [pid 22498:tid 140421352134400] (20, 1, '\xeb\xa7\x8e\xec\x9d\x80 \xeb\x8b\xa4 \xec\x9d\xb4\xec\x9b\x83 \xeb\xb9\x84\xeb\x91\x98\xea\xb8\xb0, \xeb\x82\xb4 \xea\xb9\x8c\xeb\x8b\xad\xec\x9e\x85\xeb\x8b\x88\xeb\x8b\xa4. \xed\x94\xbc\xec\x96\xb4\xeb\x82\x98\xeb\x93\xaf\xec\x9d\xb4 \xec\x95\xa0\xea\xb8\xb0 \xec\x9a\xb0\xeb\x8a\x94 \xeb\x90\x9c \xeb\xac\xb4\xec\x97\x87\xec\x9d\xb8\xec\xa7\x80 \xed\x95\x98\xeb\x82\x98\xec\x97\x90 \xec\x82\xac\xeb\x9e\x91\xea\xb3\xbc \xed\x97\xa4\xec\x9d\xbc \xeb\xb4\x85\xeb\x8b\x88\xeb\x8b\xa4.\\n\\n\xec\x95\x84\xeb\xa6\x84\xeb\x8b\xa4\xec\x9a\xb4 \xec\x8b\x9c\xec\x9d\xb8\xec\x9d\x98 \xeb\x8f\x99\xea\xb2\xbd\xea\xb3\xbc \xeb\x8b\xb9\xec\x8b\xa0\xec\x9d\x80 \xeb\x82\x98\xec\x9d\x98 \xec\x9d\xb4\xeb\xa6\x84\xec\x9e\x90\xeb\xa5\xbc \xed\x8c\x8c\xeb\x9e\x80 \xec\x98\xa4\xeb\x8a\x94 \xeb\xb3\xb4\xea\xb3\xa0, \xeb\xb4\x85\xeb\x8b\x88\xeb\x8b\xa4. \xeb\x8b\xa4 \xeb\xb3\x84 \xeb\xaa\xbb \xeb\xb6\x81\xea\xb0\x84\xeb\x8f\x84\xec\x97\x90 \xec\x95\x84\xec\xb9\xa8\xec\x9d\xb4 \xed\x95\x98\xeb\x82\x98\xec\x9d\x98 \xec\x9a\xb0\xeb\x8a\x94 \xed\x95\x98\xeb\x82\x98\xec\x97\x90 \xea\xb3\x84\xec\x8b\xad\xeb\x8b\x88\xeb\x8b\xa4. \xec\x9c\x84\xec\x97\x90 \xec\x9d\xb4\xec\xa0\x9c \xec\x86\x8c\xed\x95\x99\xea\xb5\x90 \xed\x95\x98\xeb\x82\x98\xec\x97\x90 \xeb\xb4\x84\xec\x9d\xb4 \xeb\x90\x9c \xec\x9d\xb4\xeb\xa6\x84\xea\xb3\xbc, \xec\x8b\x9c\xec\x9d\xb8\xec\x9d\x98 \xec\x9a\xb0\xeb\x8a\x94 \xeb\xb4\x85\xeb\x8b\x88\xeb\x8b\xa4. \xea\xb7\xb8\xeb\xa6\xac\xea\xb3\xa0 \xea\xb0\x95\xec\x95\x84\xec\xa7\x80, \xeb\x85\xb8\xec\x83\x88, \xea\xb1\xb0\xec\x99\xb8\xeb\x8b\xa4.', '\xeb\xa7\x8e\xec\x9d\x80 \xeb\x8b\xa4 \xec\x9d\xb4\xec\x9b\x83 \xeb\xb9\x84\xeb\x91\x98\xea\xb8\xb0, \xeb\x82\xb4 \xea\xb9\x8c\xeb\x8b\xad\xec\x9e\x85\xeb\x8b\x88\xeb\x8b\xa4. \xed\x94\xbc\xec\x96\xb4\xeb\x82\x98\xeb\x93\xaf\xec\x9d\xb4 \xec\x95\xa0\xea\xb8\xb0 \xec\x9a\xb0\xeb\x8a\x94 \xeb\x90\x9c \xeb\xac\xb4\xec\x97\x87\xec\x9d\xb8\xec\xa7\x80', 10, 2, 1, None, 'hankyul')
[Thu Sep 17 10:42:40.520075 2020] [wsgi:error] [pid 22498:tid 140421343733504] (20, 1, '\xeb\xa7\x8e\xec\x9d\x80 \xeb\x8b\xa4 \xec\x9d\xb4\xec\x9b\x83 \xeb\xb9\x84\xeb\x91\x98\xea\xb8\xb0, \xeb\x82\xb4 \xea\xb9\x8c\xeb\x8b\xad\xec\x9e\x85\xeb\x8b\x88\xeb\x8b\xa4. \xed\x94\xbc\xec\x96\xb4\xeb\x82\x98\xeb\x93\xaf\xec\x9d\xb4 \xec\x95\xa0\xea\xb8\xb0 \xec\x9a\xb0\xeb\x8a\x94 \xeb\x90\x9c \xeb\xac\xb4\xec\x97\x87\xec\x9d\xb8\xec\xa7\x80 \xed\x95\x98\xeb\x82\x98\xec\x97\x90 \xec\x82\xac\xeb\x9e\x91\xea\xb3\xbc \xed\x97\xa4\xec\x9d\xbc \xeb\xb4\x85\xeb\x8b\x88\xeb\x8b\xa4.\\n\\n\xec\x95\x84\xeb\xa6\x84\xeb\x8b\xa4\xec\x9a\xb4 \xec\x8b\x9c\xec\x9d\xb8\xec\x9d\x98 \xeb\x8f\x99\xea\xb2\xbd\xea\xb3\xbc \xeb\x8b\xb9\xec\x8b\xa0\xec\x9d\x80 \xeb\x82\x98\xec\x9d\x98 \xec\x9d\xb4\xeb\xa6\x84\xec\x9e\x90\xeb\xa5\xbc \xed\x8c\x8c\xeb\x9e\x80 \xec\x98\xa4\xeb\x8a\x94 \xeb\xb3\xb4\xea\xb3\xa0, \xeb\xb4\x85\xeb\x8b\x88\xeb\x8b\xa4. \xeb\x8b\xa4 \xeb\xb3\x84 \xeb\xaa\xbb \xeb\xb6\x81\xea\xb0\x84\xeb\x8f\x84\xec\x97\x90 \xec\x95\x84\xec\xb9\xa8\xec\x9d\xb4 \xed\x95\x98\xeb\x82\x98\xec\x9d\x98 \xec\x9a\xb0\xeb\x8a\x94 \xed\x95\x98\xeb\x82\x98\xec\x97\x90 \xea\xb3\x84\xec\x8b\xad\xeb\x8b\x88\xeb\x8b\xa4. \xec\x9c\x84\xec\x97\x90 \xec\x9d\xb4\xec\xa0\x9c \xec\x86\x8c\xed\x95\x99\xea\xb5\x90 \xed\x95\x98\xeb\x82\x98\xec\x97\x90 \xeb\xb4\x84\xec\x9d\xb4 \xeb\x90\x9c \xec\x9d\xb4\xeb\xa6\x84\xea\xb3\xbc, \xec\x8b\x9c\xec\x9d\xb8\xec\x9d\x98 \xec\x9a\xb0\xeb\x8a\x94 \xeb\xb4\x85\xeb\x8b\x88\xeb\x8b\xa4. \xea\xb7\xb8\xeb\xa6\xac\xea\xb3\xa0 \xea\xb0\x95\xec\x95\x84\xec\xa7\x80, \xeb\x85\xb8\xec\x83\x88, \xea\xb1\xb0\xec\x99\xb8\xeb\x8b\xa4.', '\xeb\xa7\x8e\xec\x9d\x80 \xeb\x8b\xa4 \xec\x9d\xb4\xec\x9b\x83 \xeb\xb9\x84\xeb\x91\x98\xea\xb8\xb0, \xeb\x82\xb4 \xea\xb9\x8c\xeb\x8b\xad\xec\x9e\x85\xeb\x8b\x88\xeb\x8b\xa4. \xed\x94\xbc\xec\x96\xb4\xeb\x82\x98\xeb\x93\xaf\xec\x9d\xb4 \xec\x95\xa0\xea\xb8\xb0 \xec\x9a\xb0\xeb\x8a\x94 \xeb\x90\x9c \xeb\xac\xb4\xec\x97\x87\xec\x9d\xb8\xec\xa7\x80', 10, 2, 1, None, 'hankyul')
[Thu Sep 17 10:42:42.610057 2020] [wsgi:error] [pid 22498:tid 140421352134400] (20, 1, '\xeb\xa7\x8e\xec\x9d\x80 \xeb\x8b\xa4 \xec\x9d\xb4\xec\x9b\x83 \xeb\xb9\x84\xeb\x91\x98\xea\xb8\xb0, \xeb\x82\xb4 \xea\xb9\x8c\xeb\x8b\xad\xec\x9e\x85\xeb\x8b\x88\xeb\x8b\xa4. \xed\x94\xbc\xec\x96\xb4\xeb\x82\x98\xeb\x93\xaf\xec\x9d\xb4 \xec\x95\xa0\xea\xb8\xb0 \xec\x9a\xb0\xeb\x8a\x94 \xeb\x90\x9c \xeb\xac\xb4\xec\x97\x87\xec\x9d\xb8\xec\xa7\x80 \xed\x95\x98\xeb\x82\x98\xec\x97\x90 \xec\x82\xac\xeb\x9e\x91\xea\xb3\xbc \xed\x97\xa4\xec\x9d\xbc \xeb\xb4\x85\xeb\x8b\x88\xeb\x8b\xa4.\\n\\n\xec\x95\x84\xeb\xa6\x84\xeb\x8b\xa4\xec\x9a\xb4 \xec\x8b\x9c\xec\x9d\xb8\xec\x9d\x98 \xeb\x8f\x99\xea\xb2\xbd\xea\xb3\xbc \xeb\x8b\xb9\xec\x8b\xa0\xec\x9d\x80 \xeb\x82\x98\xec\x9d\x98 \xec\x9d\xb4\xeb\xa6\x84\xec\x9e\x90\xeb\xa5\xbc \xed\x8c\x8c\xeb\x9e\x80 \xec\x98\xa4\xeb\x8a\x94 \xeb\xb3\xb4\xea\xb3\xa0, \xeb\xb4\x85\xeb\x8b\x88\xeb\x8b\xa4. \xeb\x8b\xa4 \xeb\xb3\x84 \xeb\xaa\xbb \xeb\xb6\x81\xea\xb0\x84\xeb\x8f\x84\xec\x97\x90 \xec\x95\x84\xec\xb9\xa8\xec\x9d\xb4 \xed\x95\x98\xeb\x82\x98\xec\x9d\x98 \xec\x9a\xb0\xeb\x8a\x94 \xed\x95\x98\xeb\x82\x98\xec\x97\x90 \xea\xb3\x84\xec\x8b\xad\xeb\x8b\x88\xeb\x8b\xa4. \xec\x9c\x84\xec\x97\x90 \xec\x9d\xb4\xec\xa0\x9c \xec\x86\x8c\xed\x95\x99\xea\xb5\x90 \xed\x95\x98\xeb\x82\x98\xec\x97\x90 \xeb\xb4\x84\xec\x9d\xb4 \xeb\x90\x9c \xec\x9d\xb4\xeb\xa6\x84\xea\xb3\xbc, \xec\x8b\x9c\xec\x9d\xb8\xec\x9d\x98 \xec\x9a\xb0\xeb\x8a\x94 \xeb\xb4\x85\xeb\x8b\x88\xeb\x8b\xa4. \xea\xb7\xb8\xeb\xa6\xac\xea\xb3\xa0 \xea\xb0\x95\xec\x95\x84\xec\xa7\x80, \xeb\x85\xb8\xec\x83\x88, \xea\xb1\xb0\xec\x99\xb8\xeb\x8b\xa4.', '\xeb\xa7\x8e\xec\x9d\x80 \xeb\x8b\xa4 \xec\x9d\xb4\xec\x9b\x83 \xeb\xb9\x84\xeb\x91\x98\xea\xb8\xb0, \xeb\x82\xb4 \xea\xb9\x8c\xeb\x8b\xad\xec\x9e\x85\xeb\x8b\x88\xeb\x8b\xa4. \xed\x94\xbc\xec\x96\xb4\xeb\x82\x98\xeb\x93\xaf\xec\x9d\xb4 \xec\x95\xa0\xea\xb8\xb0 \xec\x9a\xb0\xeb\x8a\x94 \xeb\x90\x9c \xeb\xac\xb4\xec\x97\x87\xec\x9d\xb8\xec\xa7\x80', 10, 2, 1, None, 'hankyul')
[Thu Sep 17 10:42:43.465980 2020] [wsgi:error] [pid 22498:tid 140421343733504] (20, 1, '\xeb\xa7\x8e\xec\x9d\x80 \xeb\x8b\xa4 \xec\x9d\xb4\xec\x9b\x83 \xeb\xb9\x84\xeb\x91\x98\xea\xb8\xb0, \xeb\x82\xb4 \xea\xb9\x8c\xeb\x8b\xad\xec\x9e\x85\xeb\x8b\x88\xeb\x8b\xa4. \xed\x94\xbc\xec\x96\xb4\xeb\x82\x98\xeb\x93\xaf\xec\x9d\xb4 \xec\x95\xa0\xea\xb8\xb0 \xec\x9a\xb0\xeb\x8a\x94 \xeb\x90\x9c \xeb\xac\xb4\xec\x97\x87\xec\x9d\xb8\xec\xa7\x80 \xed\x95\x98\xeb\x82\x98\xec\x97\x90 \xec\x82\xac\xeb\x9e\x91\xea\xb3\xbc \xed\x97\xa4\xec\x9d\xbc \xeb\xb4\x85\xeb\x8b\x88\xeb\x8b\xa4.\\n\\n\xec\x95\x84\xeb\xa6\x84\xeb\x8b\xa4\xec\x9a\xb4 \xec\x8b\x9c\xec\x9d\xb8\xec\x9d\x98 \xeb\x8f\x99\xea\xb2\xbd\xea\xb3\xbc \xeb\x8b\xb9\xec\x8b\xa0\xec\x9d\x80 \xeb\x82\x98\xec\x9d\x98 \xec\x9d\xb4\xeb\xa6\x84\xec\x9e\x90\xeb\xa5\xbc \xed\x8c\x8c\xeb\x9e\x80 \xec\x98\xa4\xeb\x8a\x94 \xeb\xb3\xb4\xea\xb3\xa0, \xeb\xb4\x85\xeb\x8b\x88\xeb\x8b\xa4. \xeb\x8b\xa4 \xeb\xb3\x84 \xeb\xaa\xbb \xeb\xb6\x81\xea\xb0\x84\xeb\x8f\x84\xec\x97\x90 \xec\x95\x84\xec\xb9\xa8\xec\x9d\xb4 \xed\x95\x98\xeb\x82\x98\xec\x9d\x98 \xec\x9a\xb0\xeb\x8a\x94 \xed\x95\x98\xeb\x82\x98\xec\x97\x90 \xea\xb3\x84\xec\x8b\xad\xeb\x8b\x88\xeb\x8b\xa4. \xec\x9c\x84\xec\x97\x90 \xec\x9d\xb4\xec\xa0\x9c \xec\x86\x8c\xed\x95\x99\xea\xb5\x90 \xed\x95\x98\xeb\x82\x98\xec\x97\x90 \xeb\xb4\x84\xec\x9d\xb4 \xeb\x90\x9c \xec\x9d\xb4\xeb\xa6\x84\xea\xb3\xbc, \xec\x8b\x9c\xec\x9d\xb8\xec\x9d\x98 \xec\x9a\xb0\xeb\x8a\x94 \xeb\xb4\x85\xeb\x8b\x88\xeb\x8b\xa4. \xea\xb7\xb8\xeb\xa6\xac\xea\xb3\xa0 \xea\xb0\x95\xec\x95\x84\xec\xa7\x80, \xeb\x85\xb8\xec\x83\x88, \xea\xb1\xb0\xec\x99\xb8\xeb\x8b\xa4.', '\xeb\xa7\x8e\xec\x9d\x80 \xeb\x8b\xa4 \xec\x9d\xb4\xec\x9b\x83 \xeb\xb9\x84\xeb\x91\x98\xea\xb8\xb0, \xeb\x82\xb4 \xea\xb9\x8c\xeb\x8b\xad\xec\x9e\x85\xeb\x8b\x88\xeb\x8b\xa4. \xed\x94\xbc\xec\x96\xb4\xeb\x82\x98\xeb\x93\xaf\xec\x9d\xb4 \xec\x95\xa0\xea\xb8\xb0 \xec\x9a\xb0\xeb\x8a\x94 \xeb\x90\x9c \xeb\xac\xb4\xec\x97\x87\xec\x9d\xb8\xec\xa7\x80', 10, 2, 1, None, 'hankyul')
[Thu Sep 17 10:43:55.549607 2020] [wsgi:error] [pid 28918:tid 140421343733504] [remote 180.69.96.107:0] mod_wsgi (pid=28918): Target WSGI script '/var/www/Appserver/flaskr/dodam.wsgi' cannot be loaded as Python module.
[Thu Sep 17 10:43:55.549657 2020] [wsgi:error] [pid 28918:tid 140421343733504] [remote 180.69.96.107:0] mod_wsgi (pid=28918): Exception occurred processing WSGI script '/var/www/Appserver/flaskr/dodam.wsgi'.
[Thu Sep 17 10:43:55.549814 2020] [wsgi:error] [pid 28918:tid 140421343733504] [remote 180.69.96.107:0] Traceback (most recent call last):
[Thu Sep 17 10:43:55.549837 2020] [wsgi:error] [pid 28918:tid 140421343733504] [remote 180.69.96.107:0]   File "/var/www/Appserver/flaskr/dodam.wsgi", line 3, in <module>
[Thu Sep 17 10:43:55.549842 2020] [wsgi:error] [pid 28918:tid 140421343733504] [remote 180.69.96.107:0]     hi
[Thu Sep 17 10:43:55.549856 2020] [wsgi:error] [pid 28918:tid 140421343733504] [remote 180.69.96.107:0] NameError: name 'hi' is not defined
[Thu Sep 17 16:32:06.520080 2020] [wsgi:error] [pid 28918:tid 140421343733504] [remote 185.39.11.84:45923] mod_wsgi (pid=28918): Exception occurred processing WSGI script '/var/www/Appserver/flaskr/dodam.wsgi'.
[Thu Sep 17 16:32:06.669320 2020] [wsgi:error] [pid 28918:tid 140421343733504] [remote 185.39.11.84:45923] Traceback (most recent call last):
[Thu Sep 17 16:32:06.669392 2020] [wsgi:error] [pid 28918:tid 140421343733504] [remote 185.39.11.84:45923]   File "/usr/local/lib/python3.5/dist-packages/flask/app.py", line 2464, in __call__
[Thu Sep 17 16:32:06.669397 2020] [wsgi:error] [pid 28918:tid 140421343733504] [remote 185.39.11.84:45923]     return self.wsgi_app(environ, start_response)
[Thu Sep 17 16:32:06.669404 2020] [wsgi:error] [pid 28918:tid 140421343733504] [remote 185.39.11.84:45923]   File "/usr/local/lib/python3.5/dist-packages/flask/app.py", line 2450, in wsgi_app
[Thu Sep 17 16:32:06.669418 2020] [wsgi:error] [pid 28918:tid 140421343733504] [remote 185.39.11.84:45923]     response = self.handle_exception(e)
[Thu Sep 17 16:32:06.669423 2020] [wsgi:error] [pid 28918:tid 140421343733504] [remote 185.39.11.84:45923]   File "/usr/local/lib/python3.5/dist-packages/flask/app.py", line 1867, in handle_exception
[Thu Sep 17 16:32:06.669426 2020] [wsgi:error] [pid 28918:tid 140421343733504] [remote 185.39.11.84:45923]     reraise(exc_type, exc_value, tb)
[Thu Sep 17 16:32:06.669431 2020] [wsgi:error] [pid 28918:tid 140421343733504] [remote 185.39.11.84:45923]   File "/usr/local/lib/python3.5/dist-packages/flask/_compat.py", line 39, in reraise
[Thu Sep 17 16:32:06.669433 2020] [wsgi:error] [pid 28918:tid 140421343733504] [remote 185.39.11.84:45923]     raise value
[Thu Sep 17 16:32:06.669438 2020] [wsgi:error] [pid 28918:tid 140421343733504] [remote 185.39.11.84:45923]   File "/usr/local/lib/python3.5/dist-packages/flask/app.py", line 2447, in wsgi_app
[Thu Sep 17 16:32:06.669440 2020] [wsgi:error] [pid 28918:tid 140421343733504] [remote 185.39.11.84:45923]     response = self.full_dispatch_request()
[Thu Sep 17 16:32:06.669445 2020] [wsgi:error] [pid 28918:tid 140421343733504] [remote 185.39.11.84:45923]   File "/usr/local/lib/python3.5/dist-packages/flask/app.py", line 1952, in full_dispatch_request
[Thu Sep 17 16:32:06.669448 2020] [wsgi:error] [pid 28918:tid 140421343733504] [remote 185.39.11.84:45923]     rv = self.handle_user_exception(e)
[Thu Sep 17 16:32:06.669453 2020] [wsgi:error] [pid 28918:tid 140421343733504] [remote 185.39.11.84:45923]   File "/usr/local/lib/python3.5/dist-packages/flask/app.py", line 1821, in handle_user_exception
[Thu Sep 17 16:32:06.669455 2020] [wsgi:error] [pid 28918:tid 140421343733504] [remote 185.39.11.84:45923]     reraise(exc_type, exc_value, tb)
[Thu Sep 17 16:32:06.669468 2020] [wsgi:error] [pid 28918:tid 140421343733504] [remote 185.39.11.84:45923]   File "/usr/local/lib/python3.5/dist-packages/flask/_compat.py", line 39, in reraise
[Thu Sep 17 16:32:06.669471 2020] [wsgi:error] [pid 28918:tid 140421343733504] [remote 185.39.11.84:45923]     raise value
[Thu Sep 17 16:32:06.669475 2020] [wsgi:error] [pid 28918:tid 140421343733504] [remote 185.39.11.84:45923]   File "/usr/local/lib/python3.5/dist-packages/flask/app.py", line 1950, in full_dispatch_request
[Thu Sep 17 16:32:06.669478 2020] [wsgi:error] [pid 28918:tid 140421343733504] [remote 185.39.11.84:45923]     rv = self.dispatch_request()
[Thu Sep 17 16:32:06.669482 2020] [wsgi:error] [pid 28918:tid 140421343733504] [remote 185.39.11.84:45923]   File "/usr/local/lib/python3.5/dist-packages/flask/app.py", line 1936, in dispatch_request
[Thu Sep 17 16:32:06.669484 2020] [wsgi:error] [pid 28918:tid 140421343733504] [remote 185.39.11.84:45923]     return self.view_functions[rule.endpoint](**req.view_args)
[Thu Sep 17 16:32:06.669489 2020] [wsgi:error] [pid 28918:tid 140421343733504] [remote 185.39.11.84:45923]   File "/var/www/Appserver/flaskr/manage.py", line 180, in show_entries
[Thu Sep 17 16:32:06.669491 2020] [wsgi:error] [pid 28918:tid 140421343733504] [remote 185.39.11.84:45923]     cur = g.db.execute('select title, text from entries order by id desc')
[Thu Sep 17 16:32:06.669495 2020] [wsgi:error] [pid 28918:tid 140421343733504] [remote 185.39.11.84:45923]   File "/usr/local/lib/python3.5/dist-packages/werkzeug/local.py", line 347, in __getattr__
[Thu Sep 17 16:32:06.669497 2020] [wsgi:error] [pid 28918:tid 140421343733504] [remote 185.39.11.84:45923]     return getattr(self._get_current_object(), name)
[Thu Sep 17 16:32:06.669513 2020] [wsgi:error] [pid 28918:tid 140421343733504] [remote 185.39.11.84:45923] AttributeError: '_AppCtxGlobals' object has no attribute 'db'
[Fri Sep 18 20:35:07.999597 2020] [wsgi:error] [pid 7998:tid 140421360494336] [remote 192.35.168.220:0] mod_wsgi (pid=7998): Exception occurred processing WSGI script '/var/www/Appserver/flaskr/dodam.wsgi'.
[Fri Sep 18 20:35:08.052605 2020] [wsgi:error] [pid 7998:tid 140421360494336] [remote 192.35.168.220:0] Traceback (most recent call last):
[Fri Sep 18 20:35:08.052661 2020] [wsgi:error] [pid 7998:tid 140421360494336] [remote 192.35.168.220:0]   File "/usr/local/lib/python3.5/dist-packages/flask/app.py", line 2464, in __call__
[Fri Sep 18 20:35:08.052665 2020] [wsgi:error] [pid 7998:tid 140421360494336] [remote 192.35.168.220:0]     return self.wsgi_app(environ, start_response)
[Fri Sep 18 20:35:08.052671 2020] [wsgi:error] [pid 7998:tid 140421360494336] [remote 192.35.168.220:0]   File "/usr/local/lib/python3.5/dist-packages/flask/app.py", line 2450, in wsgi_app
[Fri Sep 18 20:35:08.052673 2020] [wsgi:error] [pid 7998:tid 140421360494336] [remote 192.35.168.220:0]     response = self.handle_exception(e)
[Fri Sep 18 20:35:08.052678 2020] [wsgi:error] [pid 7998:tid 140421360494336] [remote 192.35.168.220:0]   File "/usr/local/lib/python3.5/dist-packages/flask/app.py", line 1867, in handle_exception
[Fri Sep 18 20:35:08.052693 2020] [wsgi:error] [pid 7998:tid 140421360494336] [remote 192.35.168.220:0]     reraise(exc_type, exc_value, tb)
[Fri Sep 18 20:35:08.052698 2020] [wsgi:error] [pid 7998:tid 140421360494336] [remote 192.35.168.220:0]   File "/usr/local/lib/python3.5/dist-packages/flask/_compat.py", line 39, in reraise
[Fri Sep 18 20:35:08.052700 2020] [wsgi:error] [pid 7998:tid 140421360494336] [remote 192.35.168.220:0]     raise value
[Fri Sep 18 20:35:08.052704 2020] [wsgi:error] [pid 7998:tid 140421360494336] [remote 192.35.168.220:0]   File "/usr/local/lib/python3.5/dist-packages/flask/app.py", line 2447, in wsgi_app
[Fri Sep 18 20:35:08.052706 2020] [wsgi:error] [pid 7998:tid 140421360494336] [remote 192.35.168.220:0]     response = self.full_dispatch_request()
[Fri Sep 18 20:35:08.052710 2020] [wsgi:error] [pid 7998:tid 140421360494336] [remote 192.35.168.220:0]   File "/usr/local/lib/python3.5/dist-packages/flask/app.py", line 1952, in full_dispatch_request
[Fri Sep 18 20:35:08.052720 2020] [wsgi:error] [pid 7998:tid 140421360494336] [remote 192.35.168.220:0]     rv = self.handle_user_exception(e)
[Fri Sep 18 20:35:08.052725 2020] [wsgi:error] [pid 7998:tid 140421360494336] [remote 192.35.168.220:0]   File "/usr/local/lib/python3.5/dist-packages/flask/app.py", line 1821, in handle_user_exception
[Fri Sep 18 20:35:08.052727 2020] [wsgi:error] [pid 7998:tid 140421360494336] [remote 192.35.168.220:0]     reraise(exc_type, exc_value, tb)
[Fri Sep 18 20:35:08.052731 2020] [wsgi:error] [pid 7998:tid 140421360494336] [remote 192.35.168.220:0]   File "/usr/local/lib/python3.5/dist-packages/flask/_compat.py", line 39, in reraise
[Fri Sep 18 20:35:08.052733 2020] [wsgi:error] [pid 7998:tid 140421360494336] [remote 192.35.168.220:0]     raise value
[Fri Sep 18 20:35:08.052736 2020] [wsgi:error] [pid 7998:tid 140421360494336] [remote 192.35.168.220:0]   File "/usr/local/lib/python3.5/dist-packages/flask/app.py", line 1950, in full_dispatch_request
[Fri Sep 18 20:35:08.052738 2020] [wsgi:error] [pid 7998:tid 140421360494336] [remote 192.35.168.220:0]     rv = self.dispatch_request()
[Fri Sep 18 20:35:08.052742 2020] [wsgi:error] [pid 7998:tid 140421360494336] [remote 192.35.168.220:0]   File "/usr/local/lib/python3.5/dist-packages/flask/app.py", line 1936, in dispatch_request
[Fri Sep 18 20:35:08.052744 2020] [wsgi:error] [pid 7998:tid 140421360494336] [remote 192.35.168.220:0]     return self.view_functions[rule.endpoint](**req.view_args)
[Fri Sep 18 20:35:08.052748 2020] [wsgi:error] [pid 7998:tid 140421360494336] [remote 192.35.168.220:0]   File "/var/www/Appserver/flaskr/manage.py", line 180, in show_entries
[Fri Sep 18 20:35:08.052750 2020] [wsgi:error] [pid 7998:tid 140421360494336] [remote 192.35.168.220:0]     cur = g.db.execute('select title, text from entries order by id desc')
[Fri Sep 18 20:35:08.052753 2020] [wsgi:error] [pid 7998:tid 140421360494336] [remote 192.35.168.220:0]   File "/usr/local/lib/python3.5/dist-packages/werkzeug/local.py", line 347, in __getattr__
[Fri Sep 18 20:35:08.052755 2020] [wsgi:error] [pid 7998:tid 140421360494336] [remote 192.35.168.220:0]     return getattr(self._get_current_object(), name)
[Fri Sep 18 20:35:08.052770 2020] [wsgi:error] [pid 7998:tid 140421360494336] [remote 192.35.168.220:0] AttributeError: '_AppCtxGlobals' object has no attribute 'db'
[Sat Sep 19 02:21:50.853843 2020] [wsgi:error] [pid 7998:tid 140421377296128] [remote 92.118.160.45:51811] mod_wsgi (pid=7998): Exception occurred processing WSGI script '/var/www/Appserver/flaskr/dodam.wsgi'.
[Sat Sep 19 02:21:50.854043 2020] [wsgi:error] [pid 7998:tid 140421377296128] [remote 92.118.160.45:51811] Traceback (most recent call last):
[Sat Sep 19 02:21:50.854093 2020] [wsgi:error] [pid 7998:tid 140421377296128] [remote 92.118.160.45:51811]   File "/usr/local/lib/python3.5/dist-packages/flask/app.py", line 2464, in __call__
[Sat Sep 19 02:21:50.854098 2020] [wsgi:error] [pid 7998:tid 140421377296128] [remote 92.118.160.45:51811]     return self.wsgi_app(environ, start_response)
[Sat Sep 19 02:21:50.854104 2020] [wsgi:error] [pid 7998:tid 140421377296128] [remote 92.118.160.45:51811]   File "/usr/local/lib/python3.5/dist-packages/flask/app.py", line 2450, in wsgi_app
[Sat Sep 19 02:21:50.854106 2020] [wsgi:error] [pid 7998:tid 140421377296128] [remote 92.118.160.45:51811]     response = self.handle_exception(e)
[Sat Sep 19 02:21:50.854123 2020] [wsgi:error] [pid 7998:tid 140421377296128] [remote 92.118.160.45:51811]   File "/usr/local/lib/python3.5/dist-packages/flask/app.py", line 1867, in handle_exception
[Sat Sep 19 02:21:50.854125 2020] [wsgi:error] [pid 7998:tid 140421377296128] [remote 92.118.160.45:51811]     reraise(exc_type, exc_value, tb)
[Sat Sep 19 02:21:50.854130 2020] [wsgi:error] [pid 7998:tid 140421377296128] [remote 92.118.160.45:51811]   File "/usr/local/lib/python3.5/dist-packages/flask/_compat.py", line 39, in reraise
[Sat Sep 19 02:21:50.854133 2020] [wsgi:error] [pid 7998:tid 140421377296128] [remote 92.118.160.45:51811]     raise value
[Sat Sep 19 02:21:50.854147 2020] [wsgi:error] [pid 7998:tid 140421377296128] [remote 92.118.160.45:51811]   File "/usr/local/lib/python3.5/dist-packages/flask/app.py", line 2447, in wsgi_app
[Sat Sep 19 02:21:50.854149 2020] [wsgi:error] [pid 7998:tid 140421377296128] [remote 92.118.160.45:51811]     response = self.full_dispatch_request()
[Sat Sep 19 02:21:50.854154 2020] [wsgi:error] [pid 7998:tid 140421377296128] [remote 92.118.160.45:51811]   File "/usr/local/lib/python3.5/dist-packages/flask/app.py", line 1952, in full_dispatch_request
[Sat Sep 19 02:21:50.854156 2020] [wsgi:error] [pid 7998:tid 140421377296128] [remote 92.118.160.45:51811]     rv = self.handle_user_exception(e)
[Sat Sep 19 02:21:50.854160 2020] [wsgi:error] [pid 7998:tid 140421377296128] [remote 92.118.160.45:51811]   File "/usr/local/lib/python3.5/dist-packages/flask/app.py", line 1821, in handle_user_exception
[Sat Sep 19 02:21:50.854163 2020] [wsgi:error] [pid 7998:tid 140421377296128] [remote 92.118.160.45:51811]     reraise(exc_type, exc_value, tb)
[Sat Sep 19 02:21:50.854167 2020] [wsgi:error] [pid 7998:tid 140421377296128] [remote 92.118.160.45:51811]   File "/usr/local/lib/python3.5/dist-packages/flask/_compat.py", line 39, in reraise
[Sat Sep 19 02:21:50.854169 2020] [wsgi:error] [pid 7998:tid 140421377296128] [remote 92.118.160.45:51811]     raise value
[Sat Sep 19 02:21:50.854173 2020] [wsgi:error] [pid 7998:tid 140421377296128] [remote 92.118.160.45:51811]   File "/usr/local/lib/python3.5/dist-packages/flask/app.py", line 1950, in full_dispatch_request
[Sat Sep 19 02:21:50.854175 2020] [wsgi:error] [pid 7998:tid 140421377296128] [remote 92.118.160.45:51811]     rv = self.dispatch_request()
[Sat Sep 19 02:21:50.854180 2020] [wsgi:error] [pid 7998:tid 140421377296128] [remote 92.118.160.45:51811]   File "/usr/local/lib/python3.5/dist-packages/flask/app.py", line 1936, in dispatch_request
[Sat Sep 19 02:21:50.854182 2020] [wsgi:error] [pid 7998:tid 140421377296128] [remote 92.118.160.45:51811]     return self.view_functions[rule.endpoint](**req.view_args)
[Sat Sep 19 02:21:50.854186 2020] [wsgi:error] [pid 7998:tid 140421377296128] [remote 92.118.160.45:51811]   File "/var/www/Appserver/flaskr/manage.py", line 180, in show_entries
[Sat Sep 19 02:21:50.854188 2020] [wsgi:error] [pid 7998:tid 140421377296128] [remote 92.118.160.45:51811]     cur = g.db.execute('select title, text from entries order by id desc')
[Sat Sep 19 02:21:50.854192 2020] [wsgi:error] [pid 7998:tid 140421377296128] [remote 92.118.160.45:51811]   File "/usr/local/lib/python3.5/dist-packages/werkzeug/local.py", line 347, in __getattr__
[Sat Sep 19 02:21:50.854194 2020] [wsgi:error] [pid 7998:tid 140421377296128] [remote 92.118.160.45:51811]     return getattr(self._get_current_object(), name)
[Sat Sep 19 02:21:50.854209 2020] [wsgi:error] [pid 7998:tid 140421377296128] [remote 92.118.160.45:51811] AttributeError: '_AppCtxGlobals' object has no attribute 'db'
[Sat Sep 19 06:20:35.130647 2020] [wsgi:error] [pid 7998:tid 140421360494336] [remote 80.82.70.118:50540] mod_wsgi (pid=7998): Exception occurred processing WSGI script '/var/www/Appserver/flaskr/dodam.wsgi'.
[Sat Sep 19 06:20:35.131572 2020] [wsgi:error] [pid 7998:tid 140421360494336] [remote 80.82.70.118:50540] Traceback (most recent call last):
[Sat Sep 19 06:20:35.131630 2020] [wsgi:error] [pid 7998:tid 140421360494336] [remote 80.82.70.118:50540]   File "/usr/local/lib/python3.5/dist-packages/flask/app.py", line 2464, in __call__
[Sat Sep 19 06:20:35.131634 2020] [wsgi:error] [pid 7998:tid 140421360494336] [remote 80.82.70.118:50540]     return self.wsgi_app(environ, start_response)
[Sat Sep 19 06:20:35.131641 2020] [wsgi:error] [pid 7998:tid 140421360494336] [remote 80.82.70.118:50540]   File "/usr/local/lib/python3.5/dist-packages/flask/app.py", line 2450, in wsgi_app
[Sat Sep 19 06:20:35.131644 2020] [wsgi:error] [pid 7998:tid 140421360494336] [remote 80.82.70.118:50540]     response = self.handle_exception(e)
[Sat Sep 19 06:20:35.131649 2020] [wsgi:error] [pid 7998:tid 140421360494336] [remote 80.82.70.118:50540]   File "/usr/local/lib/python3.5/dist-packages/flask/app.py", line 1867, in handle_exception
[Sat Sep 19 06:20:35.131659 2020] [wsgi:error] [pid 7998:tid 140421360494336] [remote 80.82.70.118:50540]     reraise(exc_type, exc_value, tb)
[Sat Sep 19 06:20:35.131665 2020] [wsgi:error] [pid 7998:tid 140421360494336] [remote 80.82.70.118:50540]   File "/usr/local/lib/python3.5/dist-packages/flask/_compat.py", line 39, in reraise
[Sat Sep 19 06:20:35.131667 2020] [wsgi:error] [pid 7998:tid 140421360494336] [remote 80.82.70.118:50540]     raise value
[Sat Sep 19 06:20:35.131672 2020] [wsgi:error] [pid 7998:tid 140421360494336] [remote 80.82.70.118:50540]   File "/usr/local/lib/python3.5/dist-packages/flask/app.py", line 2447, in wsgi_app
[Sat Sep 19 06:20:35.131674 2020] [wsgi:error] [pid 7998:tid 140421360494336] [remote 80.82.70.118:50540]     response = self.full_dispatch_request()
[Sat Sep 19 06:20:35.131690 2020] [wsgi:error] [pid 7998:tid 140421360494336] [remote 80.82.70.118:50540]   File "/usr/local/lib/python3.5/dist-packages/flask/app.py", line 1952, in full_dispatch_request
[Sat Sep 19 06:20:35.131692 2020] [wsgi:error] [pid 7998:tid 140421360494336] [remote 80.82.70.118:50540]     rv = self.handle_user_exception(e)
[Sat Sep 19 06:20:35.131697 2020] [wsgi:error] [pid 7998:tid 140421360494336] [remote 80.82.70.118:50540]   File "/usr/local/lib/python3.5/dist-packages/flask/app.py", line 1821, in handle_user_exception
[Sat Sep 19 06:20:35.131712 2020] [wsgi:error] [pid 7998:tid 140421360494336] [remote 80.82.70.118:50540]     reraise(exc_type, exc_value, tb)
[Sat Sep 19 06:20:35.131717 2020] [wsgi:error] [pid 7998:tid 140421360494336] [remote 80.82.70.118:50540]   File "/usr/local/lib/python3.5/dist-packages/flask/_compat.py", line 39, in reraise
[Sat Sep 19 06:20:35.131719 2020] [wsgi:error] [pid 7998:tid 140421360494336] [remote 80.82.70.118:50540]     raise value
[Sat Sep 19 06:20:35.131735 2020] [wsgi:error] [pid 7998:tid 140421360494336] [remote 80.82.70.118:50540]   File "/usr/local/lib/python3.5/dist-packages/flask/app.py", line 1950, in full_dispatch_request
[Sat Sep 19 06:20:35.131737 2020] [wsgi:error] [pid 7998:tid 140421360494336] [remote 80.82.70.118:50540]     rv = self.dispatch_request()
[Sat Sep 19 06:20:35.131742 2020] [wsgi:error] [pid 7998:tid 140421360494336] [remote 80.82.70.118:50540]   File "/usr/local/lib/python3.5/dist-packages/flask/app.py", line 1936, in dispatch_request
[Sat Sep 19 06:20:35.131744 2020] [wsgi:error] [pid 7998:tid 140421360494336] [remote 80.82.70.118:50540]     return self.view_functions[rule.endpoint](**req.view_args)
[Sat Sep 19 06:20:35.131748 2020] [wsgi:error] [pid 7998:tid 140421360494336] [remote 80.82.70.118:50540]   File "/var/www/Appserver/flaskr/manage.py", line 180, in show_entries
[Sat Sep 19 06:20:35.131751 2020] [wsgi:error] [pid 7998:tid 140421360494336] [remote 80.82.70.118:50540]     cur = g.db.execute('select title, text from entries order by id desc')
[Sat Sep 19 06:20:35.131755 2020] [wsgi:error] [pid 7998:tid 140421360494336] [remote 80.82.70.118:50540]   File "/usr/local/lib/python3.5/dist-packages/werkzeug/local.py", line 347, in __getattr__
[Sat Sep 19 06:20:35.131757 2020] [wsgi:error] [pid 7998:tid 140421360494336] [remote 80.82.70.118:50540]     return getattr(self._get_current_object(), name)
[Sat Sep 19 06:20:35.131772 2020] [wsgi:error] [pid 7998:tid 140421360494336] [remote 80.82.70.118:50540] AttributeError: '_AppCtxGlobals' object has no attribute 'db'
[Sat Sep 19 10:13:59.753212 2020] [wsgi:error] [pid 31204:tid 140421360494336] [remote 92.118.161.33:0] mod_wsgi (pid=31204): Exception occurred processing WSGI script '/var/www/Appserver/flaskr/dodam.wsgi'.
[Sat Sep 19 10:13:59.754237 2020] [wsgi:error] [pid 31204:tid 140421360494336] [remote 92.118.161.33:0] Traceback (most recent call last):
[Sat Sep 19 10:13:59.754287 2020] [wsgi:error] [pid 31204:tid 140421360494336] [remote 92.118.161.33:0]   File "/usr/local/lib/python3.5/dist-packages/flask/app.py", line 2464, in __call__
[Sat Sep 19 10:13:59.754313 2020] [wsgi:error] [pid 31204:tid 140421360494336] [remote 92.118.161.33:0]     return self.wsgi_app(environ, start_response)
[Sat Sep 19 10:13:59.754320 2020] [wsgi:error] [pid 31204:tid 140421360494336] [remote 92.118.161.33:0]   File "/usr/local/lib/python3.5/dist-packages/flask/app.py", line 2450, in wsgi_app
[Sat Sep 19 10:13:59.754322 2020] [wsgi:error] [pid 31204:tid 140421360494336] [remote 92.118.161.33:0]     response = self.handle_exception(e)
[Sat Sep 19 10:13:59.754327 2020] [wsgi:error] [pid 31204:tid 140421360494336] [remote 92.118.161.33:0]   File "/usr/local/lib/python3.5/dist-packages/flask/app.py", line 1867, in handle_exception
[Sat Sep 19 10:13:59.754330 2020] [wsgi:error] [pid 31204:tid 140421360494336] [remote 92.118.161.33:0]     reraise(exc_type, exc_value, tb)
[Sat Sep 19 10:13:59.754334 2020] [wsgi:error] [pid 31204:tid 140421360494336] [remote 92.118.161.33:0]   File "/usr/local/lib/python3.5/dist-packages/flask/_compat.py", line 39, in reraise
[Sat Sep 19 10:13:59.754336 2020] [wsgi:error] [pid 31204:tid 140421360494336] [remote 92.118.161.33:0]     raise value
[Sat Sep 19 10:13:59.754340 2020] [wsgi:error] [pid 31204:tid 140421360494336] [remote 92.118.161.33:0]   File "/usr/local/lib/python3.5/dist-packages/flask/app.py", line 2447, in wsgi_app
[Sat Sep 19 10:13:59.754343 2020] [wsgi:error] [pid 31204:tid 140421360494336] [remote 92.118.161.33:0]     response = self.full_dispatch_request()
[Sat Sep 19 10:13:59.754347 2020] [wsgi:error] [pid 31204:tid 140421360494336] [remote 92.118.161.33:0]   File "/usr/local/lib/python3.5/dist-packages/flask/app.py", line 1952, in full_dispatch_request
[Sat Sep 19 10:13:59.754350 2020] [wsgi:error] [pid 31204:tid 140421360494336] [remote 92.118.161.33:0]     rv = self.handle_user_exception(e)
[Sat Sep 19 10:13:59.754366 2020] [wsgi:error] [pid 31204:tid 140421360494336] [remote 92.118.161.33:0]   File "/usr/local/lib/python3.5/dist-packages/flask/app.py", line 1821, in handle_user_exception
[Sat Sep 19 10:13:59.754369 2020] [wsgi:error] [pid 31204:tid 140421360494336] [remote 92.118.161.33:0]     reraise(exc_type, exc_value, tb)
[Sat Sep 19 10:13:59.754373 2020] [wsgi:error] [pid 31204:tid 140421360494336] [remote 92.118.161.33:0]   File "/usr/local/lib/python3.5/dist-packages/flask/_compat.py", line 39, in reraise
[Sat Sep 19 10:13:59.754376 2020] [wsgi:error] [pid 31204:tid 140421360494336] [remote 92.118.161.33:0]     raise value
[Sat Sep 19 10:13:59.754380 2020] [wsgi:error] [pid 31204:tid 140421360494336] [remote 92.118.161.33:0]   File "/usr/local/lib/python3.5/dist-packages/flask/app.py", line 1950, in full_dispatch_request
[Sat Sep 19 10:13:59.754383 2020] [wsgi:error] [pid 31204:tid 140421360494336] [remote 92.118.161.33:0]     rv = self.dispatch_request()
[Sat Sep 19 10:13:59.754387 2020] [wsgi:error] [pid 31204:tid 140421360494336] [remote 92.118.161.33:0]   File "/usr/local/lib/python3.5/dist-packages/flask/app.py", line 1936, in dispatch_request
[Sat Sep 19 10:13:59.754390 2020] [wsgi:error] [pid 31204:tid 140421360494336] [remote 92.118.161.33:0]     return self.view_functions[rule.endpoint](**req.view_args)
[Sat Sep 19 10:13:59.754394 2020] [wsgi:error] [pid 31204:tid 140421360494336] [remote 92.118.161.33:0]   File "/var/www/Appserver/flaskr/manage.py", line 180, in show_entries
[Sat Sep 19 10:13:59.754396 2020] [wsgi:error] [pid 31204:tid 140421360494336] [remote 92.118.161.33:0]     cur = g.db.execute('select title, text from entries order by id desc')
[Sat Sep 19 10:13:59.754401 2020] [wsgi:error] [pid 31204:tid 140421360494336] [remote 92.118.161.33:0]   File "/usr/local/lib/python3.5/dist-packages/werkzeug/local.py", line 347, in __getattr__
[Sat Sep 19 10:13:59.754403 2020] [wsgi:error] [pid 31204:tid 140421360494336] [remote 92.118.161.33:0]     return getattr(self._get_current_object(), name)
[Sat Sep 19 10:13:59.754419 2020] [wsgi:error] [pid 31204:tid 140421360494336] [remote 92.118.161.33:0] AttributeError: '_AppCtxGlobals' object has no attribute 'db'
[Mon Sep 21 09:59:01.976229 2020] [wsgi:error] [pid 10550:tid 140421360494336] [remote 192.241.234.140:0] mod_wsgi (pid=10550): Exception occurred processing WSGI script '/var/www/Appserver/flaskr/dodam.wsgi'.
[Mon Sep 21 09:59:02.029703 2020] [wsgi:error] [pid 10550:tid 140421360494336] [remote 192.241.234.140:0] Traceback (most recent call last):
[Mon Sep 21 09:59:02.029787 2020] [wsgi:error] [pid 10550:tid 140421360494336] [remote 192.241.234.140:0]   File "/usr/local/lib/python3.5/dist-packages/flask/app.py", line 2464, in __call__
[Mon Sep 21 09:59:02.029792 2020] [wsgi:error] [pid 10550:tid 140421360494336] [remote 192.241.234.140:0]     return self.wsgi_app(environ, start_response)
[Mon Sep 21 09:59:02.029798 2020] [wsgi:error] [pid 10550:tid 140421360494336] [remote 192.241.234.140:0]   File "/usr/local/lib/python3.5/dist-packages/flask/app.py", line 2450, in wsgi_app
[Mon Sep 21 09:59:02.029800 2020] [wsgi:error] [pid 10550:tid 140421360494336] [remote 192.241.234.140:0]     response = self.handle_exception(e)
[Mon Sep 21 09:59:02.029806 2020] [wsgi:error] [pid 10550:tid 140421360494336] [remote 192.241.234.140:0]   File "/usr/local/lib/python3.5/dist-packages/flask/app.py", line 1867, in handle_exception
[Mon Sep 21 09:59:02.029808 2020] [wsgi:error] [pid 10550:tid 140421360494336] [remote 192.241.234.140:0]     reraise(exc_type, exc_value, tb)
[Mon Sep 21 09:59:02.029813 2020] [wsgi:error] [pid 10550:tid 140421360494336] [remote 192.241.234.140:0]   File "/usr/local/lib/python3.5/dist-packages/flask/_compat.py", line 39, in reraise
[Mon Sep 21 09:59:02.029815 2020] [wsgi:error] [pid 10550:tid 140421360494336] [remote 192.241.234.140:0]     raise value
[Mon Sep 21 09:59:02.029820 2020] [wsgi:error] [pid 10550:tid 140421360494336] [remote 192.241.234.140:0]   File "/usr/local/lib/python3.5/dist-packages/flask/app.py", line 2447, in wsgi_app
[Mon Sep 21 09:59:02.029822 2020] [wsgi:error] [pid 10550:tid 140421360494336] [remote 192.241.234.140:0]     response = self.full_dispatch_request()
[Mon Sep 21 09:59:02.029827 2020] [wsgi:error] [pid 10550:tid 140421360494336] [remote 192.241.234.140:0]   File "/usr/local/lib/python3.5/dist-packages/flask/app.py", line 1952, in full_dispatch_request
[Mon Sep 21 09:59:02.029829 2020] [wsgi:error] [pid 10550:tid 140421360494336] [remote 192.241.234.140:0]     rv = self.handle_user_exception(e)
[Mon Sep 21 09:59:02.029834 2020] [wsgi:error] [pid 10550:tid 140421360494336] [remote 192.241.234.140:0]   File "/usr/local/lib/python3.5/dist-packages/flask/app.py", line 1821, in handle_user_exception
[Mon Sep 21 09:59:02.029836 2020] [wsgi:error] [pid 10550:tid 140421360494336] [remote 192.241.234.140:0]     reraise(exc_type, exc_value, tb)
[Mon Sep 21 09:59:02.029840 2020] [wsgi:error] [pid 10550:tid 140421360494336] [remote 192.241.234.140:0]   File "/usr/local/lib/python3.5/dist-packages/flask/_compat.py", line 39, in reraise
[Mon Sep 21 09:59:02.029843 2020] [wsgi:error] [pid 10550:tid 140421360494336] [remote 192.241.234.140:0]     raise value
[Mon Sep 21 09:59:02.029847 2020] [wsgi:error] [pid 10550:tid 140421360494336] [remote 192.241.234.140:0]   File "/usr/local/lib/python3.5/dist-packages/flask/app.py", line 1950, in full_dispatch_request
[Mon Sep 21 09:59:02.029849 2020] [wsgi:error] [pid 10550:tid 140421360494336] [remote 192.241.234.140:0]     rv = self.dispatch_request()
[Mon Sep 21 09:59:02.029854 2020] [wsgi:error] [pid 10550:tid 140421360494336] [remote 192.241.234.140:0]   File "/usr/local/lib/python3.5/dist-packages/flask/app.py", line 1936, in dispatch_request
[Mon Sep 21 09:59:02.029857 2020] [wsgi:error] [pid 10550:tid 140421360494336] [remote 192.241.234.140:0]     return self.view_functions[rule.endpoint](**req.view_args)
[Mon Sep 21 09:59:02.029861 2020] [wsgi:error] [pid 10550:tid 140421360494336] [remote 192.241.234.140:0]   File "/var/www/Appserver/flaskr/manage.py", line 180, in show_entries
[Mon Sep 21 09:59:02.029863 2020] [wsgi:error] [pid 10550:tid 140421360494336] [remote 192.241.234.140:0]     cur = g.db.execute('select title, text from entries order by id desc')
[Mon Sep 21 09:59:02.029869 2020] [wsgi:error] [pid 10550:tid 140421360494336] [remote 192.241.234.140:0]   File "/usr/local/lib/python3.5/dist-packages/werkzeug/local.py", line 347, in __getattr__
[Mon Sep 21 09:59:02.029878 2020] [wsgi:error] [pid 10550:tid 140421360494336] [remote 192.241.234.140:0]     return getattr(self._get_current_object(), name)
[Mon Sep 21 09:59:02.029897 2020] [wsgi:error] [pid 10550:tid 140421360494336] [remote 192.241.234.140:0] AttributeError: '_AppCtxGlobals' object has no attribute 'db'
[Tue Sep 22 04:43:34.951583 2020] [wsgi:error] [pid 10550:tid 140421377296128] [remote 183.136.225.45:51811] mod_wsgi (pid=10550): Exception occurred processing WSGI script '/var/www/Appserver/flaskr/dodam.wsgi'.
[Tue Sep 22 04:43:34.951799 2020] [wsgi:error] [pid 10550:tid 140421377296128] [remote 183.136.225.45:51811] Traceback (most recent call last):
[Tue Sep 22 04:43:34.951899 2020] [wsgi:error] [pid 10550:tid 140421377296128] [remote 183.136.225.45:51811]   File "/usr/local/lib/python3.5/dist-packages/flask/app.py", line 2464, in __call__
[Tue Sep 22 04:43:34.951904 2020] [wsgi:error] [pid 10550:tid 140421377296128] [remote 183.136.225.45:51811]     return self.wsgi_app(environ, start_response)
[Tue Sep 22 04:43:34.951911 2020] [wsgi:error] [pid 10550:tid 140421377296128] [remote 183.136.225.45:51811]   File "/usr/local/lib/python3.5/dist-packages/flask/app.py", line 2450, in wsgi_app
[Tue Sep 22 04:43:34.951914 2020] [wsgi:error] [pid 10550:tid 140421377296128] [remote 183.136.225.45:51811]     response = self.handle_exception(e)
[Tue Sep 22 04:43:34.951918 2020] [wsgi:error] [pid 10550:tid 140421377296128] [remote 183.136.225.45:51811]   File "/usr/local/lib/python3.5/dist-packages/flask/app.py", line 1867, in handle_exception
[Tue Sep 22 04:43:34.951921 2020] [wsgi:error] [pid 10550:tid 140421377296128] [remote 183.136.225.45:51811]     reraise(exc_type, exc_value, tb)
[Tue Sep 22 04:43:34.951926 2020] [wsgi:error] [pid 10550:tid 140421377296128] [remote 183.136.225.45:51811]   File "/usr/local/lib/python3.5/dist-packages/flask/_compat.py", line 39, in reraise
[Tue Sep 22 04:43:34.951929 2020] [wsgi:error] [pid 10550:tid 140421377296128] [remote 183.136.225.45:51811]     raise value
[Tue Sep 22 04:43:34.951933 2020] [wsgi:error] [pid 10550:tid 140421377296128] [remote 183.136.225.45:51811]   File "/usr/local/lib/python3.5/dist-packages/flask/app.py", line 2447, in wsgi_app
[Tue Sep 22 04:43:34.951935 2020] [wsgi:error] [pid 10550:tid 140421377296128] [remote 183.136.225.45:51811]     response = self.full_dispatch_request()
[Tue Sep 22 04:43:34.951952 2020] [wsgi:error] [pid 10550:tid 140421377296128] [remote 183.136.225.45:51811]   File "/usr/local/lib/python3.5/dist-packages/flask/app.py", line 1952, in full_dispatch_request
[Tue Sep 22 04:43:34.951955 2020] [wsgi:error] [pid 10550:tid 140421377296128] [remote 183.136.225.45:51811]     rv = self.handle_user_exception(e)
[Tue Sep 22 04:43:34.951959 2020] [wsgi:error] [pid 10550:tid 140421377296128] [remote 183.136.225.45:51811]   File "/usr/local/lib/python3.5/dist-packages/flask/app.py", line 1821, in handle_user_exception
[Tue Sep 22 04:43:34.951962 2020] [wsgi:error] [pid 10550:tid 140421377296128] [remote 183.136.225.45:51811]     reraise(exc_type, exc_value, tb)
[Tue Sep 22 04:43:34.951967 2020] [wsgi:error] [pid 10550:tid 140421377296128] [remote 183.136.225.45:51811]   File "/usr/local/lib/python3.5/dist-packages/flask/_compat.py", line 39, in reraise
[Tue Sep 22 04:43:34.951969 2020] [wsgi:error] [pid 10550:tid 140421377296128] [remote 183.136.225.45:51811]     raise value
[Tue Sep 22 04:43:34.951973 2020] [wsgi:error] [pid 10550:tid 140421377296128] [remote 183.136.225.45:51811]   File "/usr/local/lib/python3.5/dist-packages/flask/app.py", line 1950, in full_dispatch_request
[Tue Sep 22 04:43:34.951976 2020] [wsgi:error] [pid 10550:tid 140421377296128] [remote 183.136.225.45:51811]     rv = self.dispatch_request()
[Tue Sep 22 04:43:34.951981 2020] [wsgi:error] [pid 10550:tid 140421377296128] [remote 183.136.225.45:51811]   File "/usr/local/lib/python3.5/dist-packages/flask/app.py", line 1936, in dispatch_request
[Tue Sep 22 04:43:34.951992 2020] [wsgi:error] [pid 10550:tid 140421377296128] [remote 183.136.225.45:51811]     return self.view_functions[rule.endpoint](**req.view_args)
[Tue Sep 22 04:43:34.951997 2020] [wsgi:error] [pid 10550:tid 140421377296128] [remote 183.136.225.45:51811]   File "/var/www/Appserver/flaskr/manage.py", line 180, in show_entries
[Tue Sep 22 04:43:34.952000 2020] [wsgi:error] [pid 10550:tid 140421377296128] [remote 183.136.225.45:51811]     cur = g.db.execute('select title, text from entries order by id desc')
[Tue Sep 22 04:43:34.952004 2020] [wsgi:error] [pid 10550:tid 140421377296128] [remote 183.136.225.45:51811]   File "/usr/local/lib/python3.5/dist-packages/werkzeug/local.py", line 347, in __getattr__
[Tue Sep 22 04:43:34.952006 2020] [wsgi:error] [pid 10550:tid 140421377296128] [remote 183.136.225.45:51811]     return getattr(self._get_current_object(), name)
[Tue Sep 22 04:43:34.952022 2020] [wsgi:error] [pid 10550:tid 140421377296128] [remote 183.136.225.45:51811] AttributeError: '_AppCtxGlobals' object has no attribute 'db'
